Workbook

Sheet README
A1: README / START
A2: Добавлены реальные импортированные позиции из PRICE_MASTER
A3: Смотри листы: IMPORT_SUMMARY, PRICE_MASTER_REAL, WORK_MASTER_REAL, MATERIAL_MASTER_REAL, MATERIAL_VARIANTS_REAL, RAW_MAPPING_REAL
A4: Листы REAL_TARIFF_DEFAULTS_* содержат только безопасные стартовые правила 1:1 и требуют ручной настройки.
A5: Листы REAL_NORMALIZATION_REVIEW и REAL_GAPS показывают, где ещё нужна ручная доработка.
A6: 3) MATERIAL_MASTER — канонические материалы/семейства.
A7: 4) MATERIAL_VARIANTS — варианты материала (толщина, цвет, фаска, класс нагрузки, цена).
A8: 5) RAW_MAPPING — связь сырых строк из старых прайсов с каноническими сущностями и вариантами.
A10: Базовые правила:
A11: • RawName хранить как пришло из исходника; не делать его универсальным.
A12: • CanonicalWork / CanonicalMaterial — единая нормализованная сущность.
A13: • RowNumber использовать только как след старой структуры, а не как ключ новой базы.
... A62: Смысл: шаблон перестроен из «набора примеров» в более полный каркас движка генератора КП.

Sheet CRITIQUE_AND_GAPS
A1: Layer | B1: CurrentWeakness | C1: WhyItBreaksTheGenerator | D1: WhatWasAddedInV5 | E1: Priority | F1: Status
A2: 1. Архитектура расчета | B2: Не была явно зафиксирована очередность применения правил и коэффициентов | C2: Без порядка приоритета модель начинает по-разному считать одну и ту же строку | D2: Добавлен лист CALC_PRECEDENCE с порядком применения: override → variant → site → tariff → reserve → rounding → min charges → VAT | E2: Critical | F2: Added
A3: 2. Условия объекта | B3: Были грунт/рельеф, но не было расстояния, сезона, срочности и налогового режима | C3: Коммерческая цена и логистика поедут даже при верных работах и материалах | D3: OBJECT_CONDITIONS расширен: distance, season, urgency, tax, VAT | E3: Critical | F3: Added
A4: 3. Логистика и операционные коэффициенты | B4: Отсутствовали distance/season/urgency коэффициенты | C4: Занижение маленьких, дальних и срочных объектов | D4: Добавлен OPERATING_COEFFS | E4: High | F4: Added
A5: 4. Закупка материалов | B5: Был запас, но не было правил округления закупки, MOQ и шагов заказа | C5: Генератор может посчитать правильный расход и все равно неверно заказать | D5: Добавлен PROCUREMENT_RULES | E5: Critical | F5: Added
A6: 5. Минимальные коммерческие пороги | B6: Не было minimum charge, mobilization, visit charge, floor для маленьких объектов | C6: Мелкие заказы будут системно недооценены | D6: Добавлен COMMERCIAL_POLICY | E6: Critical | F6: Added
A7: 6. Совместимость и автодобавления | B7: Не было явного слоя dependency/compatibility | C7: Смета может собрать невозможную комбинацию | D7: Добавлен DEPENDENCY_RULES | E7: High | F7: Added
A8: 7. Вывод клиенту | B8: Не было отдельной политики вывода по разделам и типам строк | C8: КП может быть либо перегружено, либо слишком пусто | D8: Добавлен OUTPUT_RULES | E8: Medium | F8: Added
A9: 8. Контроль качества данных | B9: Не было валидации обязательных полей и конфликтов | C9: Ошибки останутся тихими до момента отправки КП | D9: Добавлены VALIDATION_RULES и VALIDATION_EXAMPLE | E9: Critical | F9: Added
A10: 9. Юридические и коммерческие оговорки | B10: Не было библиотеки стандартных inclusion/exclusion/assumption | C10: Даже верная цифра без условий порождает спор с клиентом | D10: Добавлен EXCLUSIONS_LIBRARY | E10: High | F10: Added
A11: 10. Управление ценами | B11: В каталогах не хватало price source/validity/tax/lead time | C11: Нельзя контролировать устаревшие цены и происхождение цифры | D11: Расширены WORK_MASTER и MATERIAL_VARIANTS | E11: High | F11: Added
A12: 11. Внутренний и клиентский контур | B12: Не были разделены коммерческие коэффициенты и налоговый режим | C12: Смешивание sell-logic и tax приводит к двойному/нулевому НДС | D12: Добавлены TAX_MODES и логика VAT в примерах | E12: High | F12: Added
A13: 12. Итоговый пример расчета | B13: Пример был полезным, но не отражал полный расчетный стек | C13: Пользователь не видит, как сходятся все правила вместе | D13: Добавлен KP_ENGINE_V5_EXAMPLE | E13: Critical | F13: Added

Sheet CALC_PRECEDENCE
A1: StepNo | B1: Layer | C1: AppliedWhen | D1: RuleSource | E1: OutputField | F1: PriorityLogic | G1: FormulaSkeleton | H1: WhyNeeded | I1: Notes
A2: 1 | B2: Direct override | C2: Если задан ManualOverridePrice или explicit PreferredVariantID | D2: WORK_VARIANTS / ручной ввод | E2: BaseUnitPrice / Variant | F2: Override всегда бьет базу | G2: Price = ManualOverridePrice | H2: Позволяет не ломать модель там, где коэффициентами не описать | I2: Для rare cases
A3: 2 | B3: Variant resolution | C3: Когда есть Method/Variant/Tariff rules | D3: WORK_VARIANTS / MATERIAL_VARIANTS / *_TARIFF_RULES | E3: ResolvedVariantID / MethodCoeff | F3: Выбрать прямую цену варианта до общих коэффициентов | G3: Base = VariantPrice or MasterBasePrice | H3: Иначе база и вариант конфликтуют
A4: 3 | B4: Site factors | C4: Когда строка чувствительна к условиям участка | D4: WORK_FACTOR_APPLICABILITY / MATERIAL_FACTOR_APPLICABILITY / OBJECT_CONDITIONS | E4: SiteCoeff | F4: Только для чувствительных позиций | G4: Adj = 1 + Σ(weight*(coeff-1)) | H4: Иначе будет двойной учет
A5: 4 | B5: Operating factors | C5: Дальность, сезон, срочность | D5: OPERATING_COEFFS / OBJECT_CONDITIONS | E5: OperatingCoeff | F5: Применять только к work/logistics и частично к material delivery | G5: Adj = Distance*Season*Urgency | H5: Учитывает эксплуатационную реальность
A6: 5 | B6: Tariff rules | C6: Всегда при выбранном тарифе | D6: TARIFF_PROFILES / *_TARIFF_RULES | E6: TariffCoeff / display | F6: Override строки сильнее профиля тарифа | G6: Adj = TariffOverride or TariffProfile | H6: Тариф меняет не только цену, но и вывод
A7: 6 | B7: Reserve / waste | C7: Только для материалов | D7: MATERIAL_ALLOWANCES + тариф bias | E7: ReserveCoeff | F7: Сначала физический расход, затем bias тарифа | G7: PurchaseNet = NetQty * ReserveCoeff | H7: Разных причин потерь нельзя смешивать
A8: 7 | B8: Procurement rounding | C8: Только для материалов/логистики | D8: PROCUREMENT_RULES | E8: PurchaseQty | F8: Округление после запаса | G8: PurchaseQty = ROUNDUP(...) | H8: Иначе расход верный, закупка неверная
A9: 8 | B9: Commercial floors | C9: Малые объекты, выезды, мобилизация | D9: COMMERCIAL_POLICY | E9: MinCharge / Mobilization | F9: После построчного расчета и до НДС | G9: Subtotal = MAX(sum, MinQuoteValue)+charges | H9: Иначе маленькие объекты убыточны
A10: 9 | B10: VAT / tax | C10: В конце | D10: TAX_MODES / OBJECT_CONDITIONS | E10: PriceIncVAT | F10: НДС последним слоем поверх ex VAT | G10: IncVAT = ExVAT*(1+VATRate) | H10: Иначе высокий риск двойного учета
A11: 10 | B11: Output assembly | C11: После расчета | D11: OUTPUT_RULES / EXCLUSIONS_LIBRARY | E11: Client lines and notes | F11: Не меняет математику, меняет упаковку | G11: Bundle, hide, reorder, append notes | H11: Иначе хороший расчет плохо продается

Sheet DICTIONARIES
A1: Sections | B1: PositionTypes | C1: Units | D1: DisplayModes | E1: ExecutionMethods | F1: PricingModels | G1: YesNo | H1: EntityTypes | I1: MappingConfidence | J1: MappingStatus | K1: LoadClass | L1: Surface | M1: EdgeType | N1: Colors | O1: MaterialTypes | P1: SoilWorkability | Q1: SoilMoisture | R1: DebrisLevel | S1: SlopeClass | T1: UnevennessClass | U1: AccessClass | V1: TurnSpace | W1: ProximityClass | X1: MachineryAllowed | Y1: RuleAction | Z1: RuleScope | AB1: ConditionFields | AC1: AllowanceGroups | AD1: AllowanceTypes | AE1: MaterialCalcModes | AF1: GeometryComplexity | AG1: PurchaseUnits | AH1: MaterialScopeType | AI1: MaterialConditionFields | AJ1: Tariffs | AK1: TariffScope | AL1: TariffDisplayMode | AM1: SeasonClass | AN1: UrgencyClass | AO1: DistanceClass | AP1: TaxModes | AQ1: RoundingModes | AR1: PurchaseRoundBasis | AS1: Severity | AT1: ValidationRuleType | AU1: KPLineTypes | AV1: BundleModes | AW1: InclusionType | AX1: ApprovalLevel | AY1: PriceSourceType | AZ1: SortProfile
A2: Мощение | B2: Работа | C2: м2 | D2: Показать строкой | E2: Стандарт | F2: за м2 | G2: Да | H2: Work | I2: High | J2: Approved | K2: Пешеходная | L2: Гладкая | M2: Без фаски | N2: Серый | O2: Покрытие | P2: Лёгкая | Q2: Сухая | R2: Нет | S2: 0-3% | T2: Низкая | U2: Свободный | V2: Достаточно | W2: Нет влияния | X2: Да | Y2: ForceMethod | Z2: Work | AB2: SoilWorkability | AC2: Сыпучие с уплотнением | AD2: Разрыхление/уплотнение | AE2: NetQty x BaseReserveCoeff | AF2: Простая | AG2: м2 | AH2: MaterialType | AI2: GeometryComplexity | AJ2: Эконом | AK2: Work | AL2: Свернуть в раздел | AM2: Низкий сезон | AN2: Планово | AO2: До 10 км | AP2: Без НДС | AQ2: UP | AR2: По упаковке | AS2: Info | AT2: Required | AU2: Work | AV2: Минимум | AW2: Inclusion | AX2: Менеджер | AY2: Прайс поставщика | AZ2: Эконом
A3: Газон | B3: Материал | C3: м.п. | D3: Свернуть в раздел | E3: Ручной | F3: за м.п. | G3: Нет | H3: Material | I3: Medium | J3: Review | K3: Легковой транспорт | L3: Фактурная | M3: С фаской | N3: Красный | O3: Сыпучий материал | P3: Средняя | Q3: Нормальная | R3: Умеренно | S3: 3-8% | T3: Средняя | U3: Ограниченный | V3: Ограниченно | W3: Близко | X3: Частично | Y3: PreferMethod | Z3: Section | AB3: SoilMoisture | AC3: Сыпучие без уплотнения | AD3: Запас на подрезку | AE3: NetQty x BaseReserveCoeff x SiteReserveCoeff | AF3: Средняя | AG3: шт | AH3: MaterialFamily | AI3: SlopeClass | AJ3: Стандарт | AK3: Material | AL3: Показать строкой | AM3: Базовый сезон | AN3: Ускоренно | AO3: 10-30 км | AP3: С НДС 20% | AQ3: NEAREST | AR3: По паллете | AS3: Warn | AT3: AllowedList | AU3: Material | AV3: База | AW3: Exclusion | AX3: Прораб | AY3: Историческая цена | AZ3: Стандарт
A4: Дренаж | B4: Техника | C4: шт | D4: Скрыть из клиентской версии | E4: Механизированный | F4: за шт | I4: Low | J4: Draft | K4: Повышенная нагрузка | L4: Не задано | M4: Не задано | N4: Коричневый | O4: Бортовой элемент | P4: Тяжёлая | Q4: Влажная | R4: Высоко | S4: 8-15% | T4: Высокая | U4: Очень стеснённый | V4: Нет | W4: Очень близко | X4: Нет | Y4: AddNote | Z4: Material | AB4: DebrisLevel | AC4: Штучное покрытие | AD4: Запас на нахлест | AE4: DesignCompactedVolume x BaseReserveCoeff | AF4: Сложная | AG4: рулон | AH4: MaterialID | AI4: SurfaceUnevenness | AJ4: Премиум | AK4: Section | AL4: Показать строкой | AM4: Высокий сезон | AN4: Срочно | AO4: 30-60 км | AP4: С НДС 10% | AQ4: DOWN | AR4: По рулону/листу | AS4: Block | AT4: NonNegative | AU4: Logistics | AV4: Детально | AW4: Assumption | AX4: Финдир | AY4: Ручной ввод | AZ4: Премиум
A5: Ливневая канализация | B5: Логистика | C5: м3 | E5: Смешанный | F5: за м3 | K5: Не задан | N5: Черный | O5: Сетка / текстиль | P5: Очень тяжёлая | Q5: Переувлажнённая | S5: >15% | Y5: AddWork | AB5: SlopeClass | AC5: Рулонный текстиль | AD5: Запас на стыковку/подгонку | AE5: DesignCompactedVolume x BaseReserveCoeff x SiteReserveCoeff | AF5: Очень сложная | AG5: лист | AH5: AllowanceGroup | AI5: AccessClass | AM5: Зимние условия | AO5: 60+ км | AR5: По рейсу | AT5: Compatibility | AU5: Overhead | AX5: Руководитель | AY5: Расчетная | AZ5: Внутренний
A6: Освещение | B6: Накладные | C6: компл | F6: фикс | N6: Не задано | O6: Прочее | Y6: AddMaterial | AB6: SurfaceUnevenness | AC6: Рулонный газон / турф | AD6: Бой/технологический запас | AG6: пачка | AI6: ProximityToBuildings | AR6: Без округления | AT6: Flag | AU6: Service
A7: Земляные и планировочные работы | B7: Услуга | C7: смена | F7: % | O7: Пленка / мембрана | AB7: AccessClass | AC7: Пленка / мембрана | AD7: Торцовка/раскрой | AG7: м3
A8: Ступени / пандусы / бетонные элементы | C8: % | F8: по запросу | O8: Погонаж / доска | AB8: TurnSpace | AC8: Погонаж / доска | AD8: Технологический запас | AG8: м.п.
A9: Закладные / коммуникации | C9: усл. | O9: Рулонный газон | AB9: ProximityToBuildings | AC9: Линейный / штучный без существенной подрезки
A10: Демонтаж и расчистка | C10: м | AB10: MachineryAllowed
A11: Посадки и уход | C11: т
A12: Полив | C12: кг
A13: Вывоз и утилизация | C13: рулон
A14: Временные сооружения и обеспечение | C14: лист
A15: Логистика и снабжение | C15: пачка
A16: Накладные / коэффициенты
A17: Сопровождение проекта / услуги

Sheet WORK_MASTER
A1: WorkID | B1: CanonicalWork | C1: CommercialName | D1: Section | E1: Subsection | F1: PositionType | G1: Unit | H1: PricingModel | I1: BasePrice | J1: BaseMethod | K1: ClientDisplayMode | L1: Keywords | M1: BundleEligible | N1: IsActive | O1: Notes | P1: TariffSensitive | Q1: PriceSource | R1: PriceValidFrom | S1: PriceValidTo | T1: TaxMode | U1: CrewType | V1: MinCrewDays
A2: WORK-0001 | B2: Выборка ложа | C2: Подготовка ложа | D2: Мощение | E2: Подготовка основания | F2: Работа | G2: м2 | H2: за м2 | I2: 350 | J2: Стандарт | K2: Показать строкой | L2: выборка, ложе, основание | M2: Да | N2: Да | O2: Пример канонической работы | P2: Да | Q2: Историческая цена | R2: 46023 | S2: 46387 | T2: Без НДС | U2: Бригада мощения | V2: 1
A3: WORK-0002 | B3: Устройство газонного ложа | C3: Устройство газонного основания | D3: Газон | E3: Подготовка основания | F3: Работа | G3: м2 | H3: за м2 | I3: 320 | J3: Стандарт | K3: Показать строкой | L3: газонное ложе, основание газона | M3: Да | N3: Да | O3: Пример для работы с вариантами метода | P3: Да
A4: WORK-0003 | B4: Копка траншеи | C4: Разработка траншеи | D4: Закладные / коммуникации | E4: Траншеи | F4: Работа | G4: м.п. | H4: за м.п. | I4: 0 | J4: Стандарт | K4: Показать строкой | L4: траншея, кабель, копка | M4: Да | N4: Да | O4: Базовую цену заполнить | P4: Да
A5: WORK-0004 | B5: Монтаж бордюра бетонного | C5: Монтаж бордюра | D5: Мощение | E5: Бордюры | F5: Работа | G5: м.п. | H5: за м.п. | I5: 0 | J5: Стандарт | K5: Показать строкой | L5: бордюр, монтаж | M5: Да | N5: Да | P5: Да

Sheet WORK_VARIANTS
A1: VariantID | B1: WorkID | C1: ExecutionMethod | D1: ConditionTag | E1: MethodCoeff | F1: ConditionCoeff | G1: ManualOverridePrice | H1: EffectiveUnitPrice | I1: IsDefault | J1: IsActive | K1: Notes
A2: WV-0001 | B2: WORK-0001 | C2: Ручной | D2: Стандарт | E2: 1.2 | F2: 1 | I2: Нет | J2: Да | K2: Пример: коэффициент только для демонстрации
A3: WV-0002 | B3: WORK-0001 | C3: Механизированный | D3: Стандарт | E3: 0.9 | F3: 1 | I3: Нет | J3: Да
A4: WV-0003 | B4: WORK-0002 | C4: Стандарт | D4: Стандарт | E4: 1 | F4: 1 | I4: Да | J4: Да | K4: База
A5: WV-0004 | B5: WORK-0002 | C5: Ручной | D5: Стандарт | E5: 1.25 | F5: 1 | I5: Нет | J5: Да | K5: Пример, который нужно калибровать
A6: WV-0005 | B6: WORK-0002 | C6: Механизированный | D6: Стандарт | E6: 0.85 | F6: 1 | I6: Нет | J6: Да | K6: Пример, который нужно калибровать
A7: WV-0006 | B7: WORK-0002 | C7: Ручной | D7: Стесненные условия | E7: 1.25 | F7: 1.15 | I7: Нет | J7: Да | K7: Пример 2-го слоя коэффициентов

Sheet MATERIAL_MASTER
A1: MaterialID | B1: MaterialFamily | C1: CanonicalMaterial | D1: CommercialBaseName | E1: Section | F1: Subsection | G1: PositionType | H1: BaseUnit | I1: LengthMM | J1: WidthMM | K1: MaterialType | L1: DefaultClientDisplayMode | M1: IsActive | N1: Notes | O1: AllowanceGroup | P1: BaseReserveCoeff | Q1: AllowanceCalcMode | R1: TariffSensitive
A2: MAT-0001 | B2: Брусчатка бетонная | C2: Брусчатка бетонная 200x100 | D2: Брусчатка бетонная | E2: Мощение | F2: Покрытие | G2: Материал | H2: м2 | I2: 200 | J2: 100 | K2: Покрытие | L2: Показать строкой | M2: Да | N2: Одна сущность, а толщина/цвет/фаска идут в варианты | O2: Штучное покрытие | P2: 1.05 | Q2: NetQty x BaseReserveCoeff x SiteReserveCoeff | R2: Да
A3: MAT-0002 | B3: Бордюр бетонный | C3: Бордюр бетонный 1000x200x80 | D3: Бордюр бетонный | E3: Мощение | F3: Бордюры | G3: Материал | H3: шт | I3: 1000 | J3: 200 | K3: Бортовой элемент | L3: Показать строкой | M3: Да | N3: Размеры можно хранить по бизнес-логике | O3: Линейный / штучный без существенной подрезки | P3: 1.02 | Q3: NetQty x BaseReserveCoeff | R3: Да
A4: MAT-0003 | B4: Геотекстиль | C4: Геотекстиль 200 г/м2 | D4: Геотекстиль | E4: Дренаж | F4: Разделительный слой | G4: Материал | H4: м2 | K4: Сетка / текстиль | L4: Свернуть в раздел | M4: Да | N4: Базовый пример рулонного материала с нахлестом и подрезкой | O4: Рулонный текстиль | P4: 1.133 | Q4: NetQty x BaseReserveCoeff x SiteReserveCoeff | R4: Да
A5: MAT-0004 | B5: Газон рулонный | C5: Газон рулонный стандарт | D5: Газон рулонный | E5: Газон | F5: Покрытие | G5: Материал | H5: м2 | K5: Рулонный газон | L5: Показать строкой | M5: Да | N5: Запас нужен на подрезку и подгонку по геометрии | O5: Рулонный газон / турф | P5: 1.05 | Q5: NetQty x BaseReserveCoeff x SiteReserveCoeff | R5: Да
A6: MAT-0005 | B6: Пленка / мембрана | C6: Пленка / мембрана защитная | D6: Пленка / мембрана | E6: Дренаж | F6: Изоляция | G6: Материал | H6: м2 | K6: Пленка / мембрана | L6: Свернуть в раздел | M6: Да | N6: Обычно есть нахлест и подрезка | O6: Пленка / мембрана | P6: 1.154 | Q6: NetQty x BaseReserveCoeff x SiteReserveCoeff | R6: Да
A7: MAT-0006 | B7: Террасная доска | C7: Террасная доска стандарт | D7: Террасная доска | E7: Мощение | F7: Деревянные покрытия | G7: Материал | H7: м2 | K7: Погонаж / доска | L7: Показать строкой | M7: Да | N7: Нужен запас на торцовку и раскрой | O7: Погонаж / доска | P7: 1.1 | Q7: NetQty x BaseReserveCoeff x SiteReserveCoeff | R7: Да
A8: MAT-0007 | B8: Щебень фр. 20-40 | C8: Щебень фр. 20-40 | D8: Щебень | E8: Мощение | F8: Основание | G8: Материал | H8: м3 | K8: Сыпучий материал | L8: Свернуть в раздел | M8: Да | N8: От проектного уплотненного объема к закупке через коэффициент | O8: Сыпучие с уплотнением | P8: 1.18 | Q8: DesignCompactedVolume x BaseReserveCoeff x SiteReserveCoeff | R8: Да

Sheet MATERIAL_VARIANTS
A1: VariantID | B1: MaterialID | C1: ThicknessMM | D1: Color | E1: Surface | F1: EdgeType | G1: LoadClass | H1: Manufacturer | I1: PricePerUnit | J1: ClientName | K1: ClientDisplayMode | L1: IsDefault | M1: IsActive | N1: Notes | O1: PurchaseUnit | P1: CoveragePerPurchaseUnit | Q1: CoverageUnit | R1: Supplier | S1: LeadTimeDays | T1: PriceSource | U1: PriceValidFrom | V1: PriceValidTo | W1: TaxMode | X1: MOQ | Y1: OrderStepQty
A2: MV-0001 | B2: MAT-0001 | C2: 40 | D2: Серый | E2: Гладкая | F2: Без фаски | G2: Пешеходная | I2: 0 | J2: Брусчатка бетонная 200x100x40 мм | K2: Показать строкой | L2: Нет | M2: Да | N2: Пример варианта; цену заполнить | O2: м2 | P2: 1 | Q2: м2 | R2: Поставщик A | S2: 5 | T2: Прайс поставщика | U2: 46082 | V2: 46112 | W2: С НДС 20% | X2: 10 | Y2: 10
A3: MV-0002 | B3: MAT-0001 | C3: 60 | D3: Серый | E3: Гладкая | F3: Без фаски | G3: Легковой транспорт | I3: 0 | J3: Брусчатка бетонная 200x100x60 мм | K3: Показать строкой | L3: Да | M3: Да | N3: Базовый вариант для частного участка | O3: м2 | P3: 1 | Q3: м2
A4: MV-0003 | B4: MAT-0001 | C4: 80 | D4: Серый | E4: Гладкая | F4: Без фаски | G4: Повышенная нагрузка | I4: 0 | J4: Брусчатка бетонная 200x100x80 мм | K4: Показать строкой | L4: Нет | M4: Да | O4: м2 | P4: 1 | Q4: м2
A5: MV-0004 | B5: MAT-0003 | I5: 0 | J5: Геотекстиль 200 г/м2 | K5: Свернуть в раздел | L5: Да | M5: Да | N5: Площадь рулона заполни по поставщику | O5: рулон | P5: 0 | Q5: м2
A6: MV-0005 | B6: MAT-0004 | I6: 0 | J6: Газон рулонный стандарт | K6: Показать строкой | L6: Да | M6: Да | N6: Размер рулона заполни по поставщику | O6: рулон | P6: 0 | Q6: м2
A7: MV-0006 | B7: MAT-0005 | I7: 0 | J7: Пленка / мембрана защитная | K7: Свернуть в раздел | L7: Да | M7: Да | N7: Ширину рулона и покрытие укажи по поставщику | O7: рулон | P7: 0 | Q7: м2
A8: MV-0007 | B8: MAT-0006 | I8: 0 | J8: Террасная доска стандарт | K8: Показать строкой | L8: Да | M8: Да | N8: Укажи покрытие одной пачки или одной доски | O8: пачка | P8: 0 | Q8: м2
A9: MV-0008 | B9: MAT-0007 | I9: 0 | J9: Щебень фр. 20-40 | K9: Свернуть в раздел | L9: Да | M9: Да | N9: Закупка обычно в м3 или т; приведи к своей схеме | O9: м3 | P9: 1 | Q9: м3

Sheet RAW_MAPPING
A1: SourceRowID | B1: RawName | C1: SourceSheet | D1: SourceRowNumber | E1: SourceSection | F1: EntityType | G1: MasterID | H1: VariantID | I1: MappingConfidence | J1: MappingStatus | K1: NeedsReview | L1: Notes
A2: SRC-0001 | B2: Выборка ложа | C2: PRICE_MASTER | D2: 101 | E2: Мощение | F2: Work | G2: WORK-0001 | I2: High | J2: Approved | K2: Нет | L2: Прямое сопоставление
A3: SRC-0002 | B3: Устройство газонного ложа | C3: PRICE_MASTER | D3: 205 | E3: Газон | F3: Work | G3: WORK-0002 | I3: High | J3: Approved | K3: Нет | L3: Прямое сопоставление
A4: SRC-0003 | B4: Брусчатка 200*100*60 серая | C4: PRICE_MASTER | D4: 305 | E4: Мощение | F4: Material | G4: MAT-0001 | H4: MV-0002 | I4: High | J4: Approved | K4: Нет | L4: Материал связан и с Master, и с Variant

Sheet VALIDATION_RULES
A1: RuleID | B1: Scope | C1: RuleType | D1: FieldName | E1: Condition | F1: Severity | G1: UserMessage | H1: SuggestedFix | I1: Notes
A2: VR-0001 | B2: OBJECT | C2: Required | D2: SelectedTariff | E2: Всегда | F2: Block | G2: Не выбран тариф объекта | H2: Заполнить SelectedTariff в OBJECT_CONDITIONS
A3: VR-0002 | B3: OBJECT | C3: Required | D3: TaxMode | E3: Всегда | F3: Block | G3: Не указан налоговый режим | H3: Выбрать TaxMode
A4: VR-0003 | B4: OBJECT | C4: Required | D4: DistanceClass | E4: Когда есть логистика/доставка | F4: Warn | G4: Не указан класс расстояния | H4: Заполнить DistanceClass
A5: VR-0004 | B5: WORK | C5: NonNegative | D5: BasePrice | E5: Всегда | F5: Block | G5: У работы отрицательная или пустая базовая цена | H5: Заполнить BasePrice >= 0
A6: VR-0005 | B6: MATERIAL | C6: Compatibility | D6: PurchaseUnit vs CoveragePerPurchaseUnit | E6: Если материал активен | F6: Warn | G6: Не заполнены единицы закупки/покрытия | H6: Заполнить PurchaseUnit и CoveragePerPurchaseUnit
A7: VR-0006 | B7: MATERIAL | C7: Compatibility | D7: AllowanceGroup vs ProcurementRule | E7: Если материал активен | F7: Warn | G7: Нет правила закупки для AllowanceGroup | H7: Добавить PROCUREMENT_RULES
A8: VR-0007 | B8: QUOTE | C8: Flag | D8: MinQuoteValue | E8: Если итог < порога | F8: Warn | G8: Итог ниже минимальной коммерческой планки | H8: Применить floor/mobilization

Sheet VALIDATION_EXAMPLE
A1: ObjectID | B1: QuoteTariff | C1: CheckName | D1: Severity | E1: IsTriggered | F1: CheckValue | G1: ThresholdOrRule | H1: UserMessage | I1: Comment
A2: OBJ-0001 | B2: =IF($A2="","",INDEX(OBJECT_CONDITIONS!$X:$X,MATCH($A2,OBJECT_CONDITIONS!$A:$A,0))) | C2: Тариф выбран | D2: Block | E2: =IF($A2="","",IF($B2="","TRIGGER","OK")) | F2: =IF($A2="","",IF($B2="","", $B2)) | G2: SelectedTariff not blank | H2: Должен быть выбран тариф объекта
A3: OBJ-0001 | B3: =IF($A3="","",INDEX(OBJECT_CONDITIONS!$AM:$AM,MATCH($A3,OBJECT_CONDITIONS!$A:$A,0))) | C3: Налоговый режим выбран | D3: Block | E3: =IF($A3="","",IF($B3="","TRIGGER","OK")) | F3: =IF($A3="","",IF($B3="","",$B3)) | G3: TaxMode not blank | H3: Должен быть указан налоговый режим
A4: OBJ-0001 | B4: =IF($A4="","",INDEX(OBJECT_CONDITIONS!$AG:$AG,MATCH($A4,OBJECT_CONDITIONS!$A:$A,0))) | C4: Класс расстояния заполнен | D4: Warn | E4: =IF($A4="","",IF($B4="","TRIGGER","OK")) | F4: =IF($A4="","",IF($B4="","",$B4)) | G4: DistanceClass not blank | H4: Для логистики нужен класс расстояния
A5: OBJ-0001 | B5: Премиум | C5: Итог КП >= min quote floor | D5: Warn | E5: =IF(SUM(KP_ENGINE_V5_EXAMPLE!$U$2:$U$20)<INDEX(COMMERCIAL_POLICY!$B:$B,MATCH($B5,COMMERCIAL_POLICY!$A:$A,0)),"TRIGGER","OK") | F5: =SUM(KP_ENGINE_V5_EXAMPLE!$U$2:$U$20) | G5: =INDEX(COMMERCIAL_POLICY!$B:$B,MATCH($B5,COMMERCIAL_POLICY!$A:$A,0)) | H5: Итог ниже минимальной планки

Sheet OBJECT_CONDITIONS
A1: ObjectID | B1: ObjectName | C1: SoilWorkability | D1: SoilCoeff | E1: SoilMoisture | F1: MoistureCoeff | G1: DebrisLevel | H1: DebrisCoeff | I1: SlopeClass | J1: SlopeCoeff | K1: SurfaceUnevenness | L1: UnevennessCoeff | M1: AccessClass | N1: AccessCoeff | O1: TurnSpace | P1: TurnSpaceCoeff | Q1: ProximityToBuildings | R1: ProximityCoeff | S1: MachineryAllowed | T1: MachineryCoeff | U1: Notes | V1: GeometryComplexity | W1: GeometryCoeff | X1: SelectedTariff | Y1: TariffWorkCoeff | Z1: TariffMaterialCoeff | AA1: TariffLogisticsCoeff | AB1: TariffOverheadCoeff | AC1: TariffReserveBiasCoeff | AD1: TariffDisplayMode | AE1: TariffNotes | AF1: DistanceFromBaseKM | AG1: DistanceClass | AH1: DistanceCoeff | AI1: SeasonClass | AJ1: SeasonCoeff | AK1: UrgencyClass | AL1: UrgencyCoeff | AM1: TaxMode | AN1: VATRate | AO1: LogisticsTrips | AP1: DisposalDistanceKM
A2: OBJ-0001 | B2: Частный участок — базовый сложный кейс | C2: Тяжёлая | D2: =IF($C2="","",SUMIFS(SITE_COEFFS!$C:$C,SITE_COEFFS!$A:$A,"SoilWorkability",SITE_COEFFS!$B:$B,$C2)) | E2: Влажная | F2: =IF($E2="","",SUMIFS(SITE_COEFFS!$C:$C,SITE_COEFFS!$A:$A,"SoilMoisture",SITE_COEFFS!$B:$B,$E2)) | G2: Умеренно | H2: =IF($G2="","",SUMIFS(SITE_COEFFS!$C:$C,SITE_COEFFS!$A:$A,"DebrisLevel",SITE_COEFFS!$B:$B,$G2)) | I2: 8-15% | J2: =IF($I2="","",SUMIFS(SITE_COEFFS!$C:$C,SITE_COEFFS!$A:$A,"SlopeClass",SITE_COEFFS!$B:$B,$I2)) | K2: Средняя | L2: =IF($K2="","",SUMIFS(SITE_COEFFS!$C:$C,SITE_COEFFS!$A:$A,"SurfaceUnevenness",SITE_COEFFS!$B:$B,$K2)) | M2: Ограниченный | N2: =IF($M2="","",SUMIFS(SITE_COEFFS!$C:$C,SITE_COEFFS!$A:$A,"AccessClass",SITE_COEFFS!$B:$B,$M2)) | O2: Ограниченно | P2: =IF($O2="","",SUMIFS(SITE_COEFFS!$C:$C,SITE_COEFFS!$A:$A,"TurnSpace",SITE_COEFFS!$B:$B,$O2)) | Q2: Близко | R2: =IF($Q2="","",SUMIFS(SITE_COEFFS!$C:$C,SITE_COEFFS!$A:$A,"ProximityToBuildings",SITE_COEFFS!$B:$B,$Q2)) | S2: Частично | T2: =IF($S2="","",SUMIFS(SITE_COEFFS!$C:$C,SITE_COEFFS!$A:$A,"MachineryAllowed",SITE_COEFFS!$B:$B,$S2)) | U2: Пример объекта для проверки формул | V2: Сложная | W2: =IF($V2="","",SUMIFS(SITE_COEFFS!$C:$C,SITE_COEFFS!$A:$A,"GeometryComplexity",SITE_COEFFS!$B:$B,$V2)) | Y2: =IF($X2="","",SUMIFS(TARIFF_PROFILES!$D:$D,TARIFF_PROFILES!$A:$A,$X2)) | Z2: =IF($X2="","",SUMIFS(TARIFF_PROFILES!$E:$E,TARIFF_PROFILES!$A:$A,$X2)) | AA2: =IF($X2="","",SUMIFS(TARIFF_PROFILES!$F:$F,TARIFF_PROFILES!$A:$A,$X2)) | AB2: =IF($X2="","",SUMIFS(TARIFF_PROFILES!$G:$G,TARIFF_PROFILES!$A:$A,$X2)) | AC2: =IF($X2="","",SUMIFS(TARIFF_PROFILES!$H:$H,TARIFF_PROFILES!$A:$A,$X2)) | AD2: =IF($X2="","",INDEX(TARIFF_PROFILES!$J:$J,MATCH($X2,TARIFF_PROFILES!$A:$A,0))) | AE2: =IF($X2="","",INDEX(TARIFF_PROFILES!$K:$K,MATCH($X2,TARIFF_PROFILES!$A:$A,0))) | AF2: 35 | AG2: 30-60 км | AH2: =IF($AG2="","",SUMIFS(OPERATING_COEFFS!$C:$C,OPERATING_COEFFS!$A:$A,"DistanceClass",OPERATING_COEFFS!$B:$B,$AG2)) | AI2: Высокий сезон | AJ2: =IF($AI2="","",SUMIFS(OPERATING_COEFFS!$C:$C,OPERATING_COEFFS!$A:$A,"SeasonClass",OPERATING_COEFFS!$B:$B,$AI2)) | AK2: Ускоренно | AL2: =IF($AK2="","",SUMIFS(OPERATING_COEFFS!$C:$C,OPERATING_COEFFS!$A:$A,"UrgencyClass",OPERATING_COEFFS!$B:$B,$AK2)) | AM2: С НДС 20% | AN2: =IF($AM2="","",INDEX(TAX_MODES!$B:$B,MATCH($AM2,TAX_MODES!$A:$A,0))) | AO2: 3 | AP2: 25
A3: OBJ-0002 | B3: Частный участок — лёгкие условия | C3: Лёгкая | D3: =IF($C3="","",SUMIFS(SITE_COEFFS!$C:$C,SITE_COEFFS!$A:$A,"SoilWorkability",SITE_COEFFS!$B:$B,$C3)) | E3: Нормальная | F3: =IF($E3="","",SUMIFS(SITE_COEFFS!$C:$C,SITE_COEFFS!$A:$A,"SoilMoisture",SITE_COEFFS!$B:$B,$E3)) | G3: Нет | H3: =IF($G3="","",SUMIFS(SITE_COEFFS!$C:$C,SITE_COEFFS!$A:$A,"DebrisLevel",SITE_COEFFS!$B:$B,$G3)) | I3: 0-3% | J3: =IF($I3="","",SUMIFS(SITE_COEFFS!$C:$C,SITE_COEFFS!$A:$A,"SlopeClass",SITE_COEFFS!$B:$B,$I3)) | K3: Низкая | L3: =IF($K3="","",SUMIFS(SITE_COEFFS!$C:$C,SITE_COEFFS!$A:$A,"SurfaceUnevenness",SITE_COEFFS!$B:$B,$K3)) | M3: Свободный | N3: =IF($M3="","",SUMIFS(SITE_COEFFS!$C:$C,SITE_COEFFS!$A:$A,"AccessClass",SITE_COEFFS!$B:$B,$M3)) | O3: Достаточно | P3: =IF($O3="","",SUMIFS(SITE_COEFFS!$C:$C,SITE_COEFFS!$A:$A,"TurnSpace",SITE_COEFFS!$B:$B,$O3)) | Q3: Нет влияния | R3: =IF($Q3="","",SUMIFS(SITE_COEFFS!$C:$C,SITE_COEFFS!$A:$A,"ProximityToBuildings",SITE_COEFFS!$B:$B,$Q3)) | S3: Да | T3: =IF($S3="","",SUMIFS(SITE_COEFFS!$C:$C,SITE_COEFFS!$A:$A,"MachineryAllowed",SITE_COEFFS!$B:$B,$S3)) | U3: Ровный участок с нормальным доступом | V3: Простая | W3: =IF($V3="","",SUMIFS(SITE_COEFFS!$C:$C,SITE_COEFFS!$A:$A,"GeometryComplexity",SITE_COEFFS!$B:$B,$V3)) | Y3: =IF($X3="","",SUMIFS(TARIFF_PROFILES!$D:$D,TARIFF_PROFILES!$A:$A,$X3)) | Z3: =IF($X3="","",SUMIFS(TARIFF_PROFILES!$E:$E,TARIFF_PROFILES!$A:$A,$X3)) | AA3: =IF($X3="","",SUMIFS(TARIFF_PROFILES!$F:$F,TARIFF_PROFILES!$A:$A,$X3)) | AB3: =IF($X3="","",SUMIFS(TARIFF_PROFILES!$G:$G,TARIFF_PROFILES!$A:$A,$X3)) | AC3: =IF($X3="","",SUMIFS(TARIFF_PROFILES!$H:$H,TARIFF_PROFILES!$A:$A,$X3)) | AD3: =IF($X3="","",INDEX(TARIFF_PROFILES!$J:$J,MATCH($X3,TARIFF_PROFILES!$A:$A,0))) | AE3: =IF($X3="","",INDEX(TARIFF_PROFILES!$K:$K,MATCH($X3,TARIFF_PROFILES!$A:$A,0))) | AF3: 8 | AG3: До 10 км | AH3: =IF($AG3="","",SUMIFS(OPERATING_COEFFS!$C:$C,OPERATING_COEFFS!$A:$A,"DistanceClass",OPERATING_COEFFS!$B:$B,$AG3)) | AI3: Базовый сезон | AJ3: =IF($AI3="","",SUMIFS(OPERATING_COEFFS!$C:$C,OPERATING_COEFFS!$A:$A,"SeasonClass",OPERATING_COEFFS!$B:$B,$AI3)) | AK3: Планово | AL3: =IF($AK3="","",SUMIFS(OPERATING_COEFFS!$C:$C,OPERATING_COEFFS!$A:$A,"UrgencyClass",OPERATING_COEFFS!$B:$B,$AK3)) | AM3: Без НДС | AN3: =IF($AM3="","",INDEX(TAX_MODES!$B:$B,MATCH($AM3,TAX_MODES!$A:$A,0))) | AO3: 1 | AP3: 5
D4: =IF($C4="","",SUMIFS(SITE_COEFFS!$C:$C,SITE_COEFFS!$A:$A,"SoilWorkability",SITE_COEFFS!$B:$B,$C4)) | F4: =IF($E4="","",SUMIFS(SITE_COEFFS!$C:$C,SITE_COEFFS!$A:$A,"SoilMoisture",SITE_COEFFS!$B:$B,$E4)) | H4: =IF($G4="","",SUMIFS(SITE_COEFFS!$C:$C,SITE_COEFFS!$A:$A,"DebrisLevel",SITE_COEFFS!$B:$B,$G4)) | J4: =IF($I4="","",SUMIFS(SITE_COEFFS!$C:$C,SITE_COEFFS!$A:$A,"SlopeClass",SITE_COEFFS!$B:$B,$I4)) | L4: =IF($K4="","",SUMIFS(SITE_COEFFS!$C:$C,SITE_COEFFS!$A:$A,"SurfaceUnevenness",SITE_COEFFS!$B:$B,$K4)) | N4: =IF($M4="","",SUMIFS(SITE_COEFFS!$C:$C,SITE_COEFFS!$A:$A,"AccessClass",SITE_COEFFS!$B:$B,$M4)) | P4: =IF($O4="","",SUMIFS(SITE_COEFFS!$C:$C,SITE_COEFFS!$A:$A,"TurnSpace",SITE_COEFFS!$B:$B,$O4)) | R4: =IF($Q4="","",SUMIFS(SITE_COEFFS!$C:$C,SITE_COEFFS!$A:$A,"ProximityToBuildings",SITE_COEFFS!$B:$B,$Q4)) | T4: =IF($S4="","",SUMIFS(SITE_COEFFS!$C:$C,SITE_COEFFS!$A:$A,"MachineryAllowed",SITE_COEFFS!$B:$B,$S4)) | W4: =IF($V4="","",SUMIFS(SITE_COEFFS!$C:$C,SITE_COEFFS!$A:$A,"GeometryComplexity",SITE_COEFFS!$B:$B,$V4)) | Y4: =IF($X4="","",SUMIFS(TARIFF_PROFILES!$D:$D,TARIFF_PROFILES!$A:$A,$X4)) | Z4: =IF($X4="","",SUMIFS(TARIFF_PROFILES!$E:$E,TARIFF_PROFILES!$A:$A,$X4)) | AA4: =IF($X4="","",SUMIFS(TARIFF_PROFILES!$F:$F,TARIFF_PROFILES!$A:$A,$X4)) | AB4: =IF($X4="","",SUMIFS(TARIFF_PROFILES!$G:$G,TARIFF_PROFILES!$A:$A,$X4)) | AC4: =IF($X4="","",SUMIFS(TARIFF_PROFILES!$H:$H,TARIFF_PROFILES!$A:$A,$X4)) | AD4: =IF($X4="","",INDEX(TARIFF_PROFILES!$J:$J,MATCH($X4,TARIFF_PROFILES!$A:$A,0))) | AE4: =IF($X4="","",INDEX(TARIFF_PROFILES!$K:$K,MATCH($X4,TARIFF_PROFILES!$A:$A,0))) | AH4: =IF($AG4="","",SUMIFS(OPERATING_COEFFS!$C:$C,OPERATING_COEFFS!$A:$A,"DistanceClass",OPERATING_COEFFS!$B:$B,$AG4)) | AJ4: =IF($AI4="","",SUMIFS(OPERATING_COEFFS!$C:$C,OPERATING_COEFFS!$A:$A,"SeasonClass",OPERATING_COEFFS!$B:$B,$AI4)) | AL4: =IF($AK4="","",SUMIFS(OPERATING_COEFFS!$C:$C,OPERATING_COEFFS!$A:$A,"UrgencyClass",OPERATING_COEFFS!$B:$B,$AK4)) | AN4: =IF($AM4="","",INDEX(TAX_MODES!$B:$B,MATCH($AM4,TAX_MODES!$A:$A,0)))
D5: =IF($C5="","",SUMIFS(SITE_COEFFS!$C:$C,SITE_COEFFS!$A:$A,"SoilWorkability",SITE_COEFFS!$B:$B,$C5)) | F5: =IF($E5="","",SUMIFS(SITE_COEFFS!$C:$C,SITE_COEFFS!$A:$A,"SoilMoisture",SITE_COEFFS!$B:$B,$E5)) | H5: =IF($G5="","",SUMIFS(SITE_COEFFS!$C:$C,SITE_COEFFS!$A:$A,"DebrisLevel",SITE_COEFFS!$B:$B,$G5)) | J5: =IF($I5="","",SUMIFS(SITE_COEFFS!$C:$C,SITE_COEFFS!$A:$A,"SlopeClass",SITE_COEFFS!$B:$B,$I5)) | L5: =IF($K5="","",SUMIFS(SITE_COEFFS!$C:$C,SITE_COEFFS!$A:$A,"SurfaceUnevenness",SITE_COEFFS!$B:$B,$K5)) | N5: =IF($M5="","",SUMIFS(SITE_COEFFS!$C:$C,SITE_COEFFS!$A:$A,"AccessClass",SITE_COEFFS!$B:$B,$M5)) | P5: =IF($O5="","",SUMIFS(SITE_COEFFS!$C:$C,SITE_COEFFS!$A:$A,"TurnSpace",SITE_COEFFS!$B:$B,$O5)) | R5: =IF($Q5="","",SUMIFS(SITE_COEFFS!$C:$C,SITE_COEFFS!$A:$A,"ProximityToBuildings",SITE_COEFFS!$B:$B,$Q5)) | T5: =IF($S5="","",SUMIFS(SITE_COEFFS!$C:$C,SITE_COEFFS!$A:$A,"MachineryAllowed",SITE_COEFFS!$B:$B,$S5)) | W5: =IF($V5="","",SUMIFS(SITE_COEFFS!$C:$C,SITE_COEFFS!$A:$A,"GeometryComplexity",SITE_COEFFS!$B:$B,$V5)) | Y5: =IF($X5="","",SUMIFS(TARIFF_PROFILES!$D:$D,TARIFF_PROFILES!$A:$A,$X5)) | Z5: =IF($X5="","",SUMIFS(TARIFF_PROFILES!$E:$E,TARIFF_PROFILES!$A:$A,$X5)) | AA5: =IF($X5="","",SUMIFS(TARIFF_PROFILES!$F:$F,TARIFF_PROFILES!$A:$A,$X5)) | AB5: =IF($X5="","",SUMIFS(TARIFF_PROFILES!$G:$G,TARIFF_PROFILES!$A:$A,$X5)) | AC5: =IF($X5="","",SUMIFS(TARIFF_PROFILES!$H:$H,TARIFF_PROFILES!$A:$A,$X5)) | AD5: =IF($X5="","",INDEX(TARIFF_PROFILES!$J:$J,MATCH($X5,TARIFF_PROFILES!$A:$A,0))) | AE5: =IF($X5="","",INDEX(TARIFF_PROFILES!$K:$K,MATCH($X5,TARIFF_PROFILES!$A:$A,0))) | AH5: =IF($AG5="","",SUMIFS(OPERATING_COEFFS!$C:$C,OPERATING_COEFFS!$A:$A,"DistanceClass",OPERATING_COEFFS!$B:$B,$AG5)) | AJ5: =IF($AI5="","",SUMIFS(OPERATING_COEFFS!$C:$C,OPERATING_COEFFS!$A:$A,"SeasonClass",OPERATING_COEFFS!$B:$B,$AI5)) | AL5: =IF($AK5="","",SUMIFS(OPERATING_COEFFS!$C:$C,OPERATING_COEFFS!$A:$A,"UrgencyClass",OPERATING_COEFFS!$B:$B,$AK5)) | AN5: =IF($AM5="","",INDEX(TAX_MODES!$B:$B,MATCH($AM5,TAX_MODES!$A:$A,0)))
D6: =IF($C6="","",SUMIFS(SITE_COEFFS!$C:$C,SITE_COEFFS!$A:$A,"SoilWorkability",SITE_COEFFS!$B:$B,$C6)) | F6: =IF($E6="","",SUMIFS(SITE_COEFFS!$C:$C,SITE_COEFFS!$A:$A,"SoilMoisture",SITE_COEFFS!$B:$B,$E6)) | H6: =IF($G6="","",SUMIFS(SITE_COEFFS!$C:$C,SITE_COEFFS!$A:$A,"DebrisLevel",SITE_COEFFS!$B:$B,$G6)) | J6: =IF($I6="","",SUMIFS(SITE_COEFFS!$C:$C,SITE_COEFFS!$A:$A,"SlopeClass",SITE_COEFFS!$B:$B,$I6)) | L6: =IF($K6="","",SUMIFS(SITE_COEFFS!$C:$C,SITE_COEFFS!$A:$A,"SurfaceUnevenness",SITE_COEFFS!$B:$B,$K6)) | N6: =IF($M6="","",SUMIFS(SITE_COEFFS!$C:$C,SITE_COEFFS!$A:$A,"AccessClass",SITE_COEFFS!$B:$B,$M6)) | P6: =IF($O6="","",SUMIFS(SITE_COEFFS!$C:$C,SITE_COEFFS!$A:$A,"TurnSpace",SITE_COEFFS!$B:$B,$O6)) | R6: =IF($Q6="","",SUMIFS(SITE_COEFFS!$C:$C,SITE_COEFFS!$A:$A,"ProximityToBuildings",SITE_COEFFS!$B:$B,$Q6)) | T6: =IF($S6="","",SUMIFS(SITE_COEFFS!$C:$C,SITE_COEFFS!$A:$A,"MachineryAllowed",SITE_COEFFS!$B:$B,$S6)) | W6: =IF($V6="","",SUMIFS(SITE_COEFFS!$C:$C,SITE_COEFFS!$A:$A,"GeometryComplexity",SITE_COEFFS!$B:$B,$V6)) | Y6: =IF($X6="","",SUMIFS(TARIFF_PROFILES!$D:$D,TARIFF_PROFILES!$A:$A,$X6)) | Z6: =IF($X6="","",SUMIFS(TARIFF_PROFILES!$E:$E,TARIFF_PROFILES!$A:$A,$X6)) | AA6: =IF($X6="","",SUMIFS(TARIFF_PROFILES!$F:$F,TARIFF_PROFILES!$A:$A,$X6)) | AB6: =IF($X6="","",SUMIFS(TARIFF_PROFILES!$G:$G,TARIFF_PROFILES!$A:$A,$X6)) | AC6: =IF($X6="","",SUMIFS(TARIFF_PROFILES!$H:$H,TARIFF_PROFILES!$A:$A,$X6)) | AD6: =IF($X6="","",INDEX(TARIFF_PROFILES!$J:$J,MATCH($X6,TARIFF_PROFILES!$A:$A,0))) | AE6: =IF($X6="","",INDEX(TARIFF_PROFILES!$K:$K,MATCH($X6,TARIFF_PROFILES!$A:$A,0))) | AH6: =IF($AG6="","",SUMIFS(OPERATING_COEFFS!$C:$C,OPERATING_COEFFS!$A:$A,"DistanceClass",OPERATING_COEFFS!$B:$B,$AG6)) | AJ6: =IF($AI6="","",SUMIFS(OPERATING_COEFFS!$C:$C,OPERATING_COEFFS!$A:$A,"SeasonClass",OPERATING_COEFFS!$B:$B,$AI6)) | AL6: =IF($AK6="","",SUMIFS(OPERATING_COEFFS!$C:$C,OPERATING_COEFFS!$A:$A,"UrgencyClass",OPERATING_COEFFS!$B:$B,$AK6)) | AN6: =IF($AM6="","",INDEX(TAX_MODES!$B:$B,MATCH($AM6,TAX_MODES!$A:$A,0)))
D7: =IF($C7="","",SUMIFS(SITE_COEFFS!$C:$C,SITE_COEFFS!$A:$A,"SoilWorkability",SITE_COEFFS!$B:$B,$C7)) | F7: =IF($E7="","",SUMIFS(SITE_COEFFS!$C:$C,SITE_COEFFS!$A:$A,"SoilMoisture",SITE_COEFFS!$B:$B,$E7)) | H7: =IF($G7="","",SUMIFS(SITE_COEFFS!$C:$C,SITE_COEFFS!$A:$A,"DebrisLevel",SITE_COEFFS!$B:$B,$G7)) | J7: =IF($I7="","",SUMIFS(SITE_COEFFS!$C:$C,SITE_COEFFS!$A:$A,"SlopeClass",SITE_COEFFS!$B:$B,$I7)) | L7: =IF($K7="","",SUMIFS(SITE_COEFFS!$C:$C,SITE_COEFFS!$A:$A,"SurfaceUnevenness",SITE_COEFFS!$B:$B,$K7)) | N7: =IF($M7="","",SUMIFS(SITE_COEFFS!$C:$C,SITE_COEFFS!$A:$A,"AccessClass",SITE_COEFFS!$B:$B,$M7)) | P7: =IF($O7="","",SUMIFS(SITE_COEFFS!$C:$C,SITE_COEFFS!$A:$A,"TurnSpace",SITE_COEFFS!$B:$B,$O7)) | R7: =IF($Q7="","",SUMIFS(SITE_COEFFS!$C:$C,SITE_COEFFS!$A:$A,"ProximityToBuildings",SITE_COEFFS!$B:$B,$Q7)) | T7: =IF($S7="","",SUMIFS(SITE_COEFFS!$C:$C,SITE_COEFFS!$A:$A,"MachineryAllowed",SITE_COEFFS!$B:$B,$S7)) | W7: =IF($V7="","",SUMIFS(SITE_COEFFS!$C:$C,SITE_COEFFS!$A:$A,"GeometryComplexity",SITE_COEFFS!$B:$B,$V7)) | Y7: =IF($X7="","",SUMIFS(TARIFF_PROFILES!$D:$D,TARIFF_PROFILES!$A:$A,$X7)) | Z7: =IF($X7="","",SUMIFS(TARIFF_PROFILES!$E:$E,TARIFF_PROFILES!$A:$A,$X7)) | AA7: =IF($X7="","",SUMIFS(TARIFF_PROFILES!$F:$F,TARIFF_PROFILES!$A:$A,$X7)) | AB7: =IF($X7="","",SUMIFS(TARIFF_PROFILES!$G:$G,TARIFF_PROFILES!$A:$A,$X7)) | AC7: =IF($X7="","",SUMIFS(TARIFF_PROFILES!$H:$H,TARIFF_PROFILES!$A:$A,$X7)) | AD7: =IF($X7="","",INDEX(TARIFF_PROFILES!$J:$J,MATCH($X7,TARIFF_PROFILES!$A:$A,0))) | AE7: =IF($X7="","",INDEX(TARIFF_PROFILES!$K:$K,MATCH($X7,TARIFF_PROFILES!$A:$A,0))) | AH7: =IF($AG7="","",SUMIFS(OPERATING_COEFFS!$C:$C,OPERATING_COEFFS!$A:$A,"DistanceClass",OPERATING_COEFFS!$B:$B,$AG7)) | AJ7: =IF($AI7="","",SUMIFS(OPERATING_COEFFS!$C:$C,OPERATING_COEFFS!$A:$A,"SeasonClass",OPERATING_COEFFS!$B:$B,$AI7)) | AL7: =IF($AK7="","",SUMIFS(OPERATING_COEFFS!$C:$C,OPERATING_COEFFS!$A:$A,"UrgencyClass",OPERATING_COEFFS!$B:$B,$AK7)) | AN7: =IF($AM7="","",INDEX(TAX_MODES!$B:$B,MATCH($AM7,TAX_MODES!$A:$A,0)))
D8: =IF($C8="","",SUMIFS(SITE_COEFFS!$C:$C,SITE_COEFFS!$A:$A,"SoilWorkability",SITE_COEFFS!$B:$B,$C8)) | F8: =IF($E8="","",SUMIFS(SITE_COEFFS!$C:$C,SITE_COEFFS!$A:$A,"SoilMoisture",SITE_COEFFS!$B:$B,$E8)) | H8: =IF($G8="","",SUMIFS(SITE_COEFFS!$C:$C,SITE_COEFFS!$A:$A,"DebrisLevel",SITE_COEFFS!$B:$B,$G8)) | J8: =IF($I8="","",SUMIFS(SITE_COEFFS!$C:$C,SITE_COEFFS!$A:$A,"SlopeClass",SITE_COEFFS!$B:$B,$I8)) | L8: =IF($K8="","",SUMIFS(SITE_COEFFS!$C:$C,SITE_COEFFS!$A:$A,"SurfaceUnevenness",SITE_COEFFS!$B:$B,$K8)) | N8: =IF($M8="","",SUMIFS(SITE_COEFFS!$C:$C,SITE_COEFFS!$A:$A,"AccessClass",SITE_COEFFS!$B:$B,$M8)) | P8: =IF($O8="","",SUMIFS(SITE_COEFFS!$C:$C,SITE_COEFFS!$A:$A,"TurnSpace",SITE_COEFFS!$B:$B,$O8)) | R8: =IF($Q8="","",SUMIFS(SITE_COEFFS!$C:$C,SITE_COEFFS!$A:$A,"ProximityToBuildings",SITE_COEFFS!$B:$B,$Q8)) | T8: =IF($S8="","",SUMIFS(SITE_COEFFS!$C:$C,SITE_COEFFS!$A:$A,"MachineryAllowed",SITE_COEFFS!$B:$B,$S8)) | W8: =IF($V8="","",SUMIFS(SITE_COEFFS!$C:$C,SITE_COEFFS!$A:$A,"GeometryComplexity",SITE_COEFFS!$B:$B,$V8)) | Y8: =IF($X8="","",SUMIFS(TARIFF_PROFILES!$D:$D,TARIFF_PROFILES!$A:$A,$X8)) | Z8: =IF($X8="","",SUMIFS(TARIFF_PROFILES!$E:$E,TARIFF_PROFILES!$A:$A,$X8)) | AA8: =IF($X8="","",SUMIFS(TARIFF_PROFILES!$F:$F,TARIFF_PROFILES!$A:$A,$X8)) | AB8: =IF($X8="","",SUMIFS(TARIFF_PROFILES!$G:$G,TARIFF_PROFILES!$A:$A,$X8)) | AC8: =IF($X8="","",SUMIFS(TARIFF_PROFILES!$H:$H,TARIFF_PROFILES!$A:$A,$X8)) | AD8: =IF($X8="","",INDEX(TARIFF_PROFILES!$J:$J,MATCH($X8,TARIFF_PROFILES!$A:$A,0))) | AE8: =IF($X8="","",INDEX(TARIFF_PROFILES!$K:$K,MATCH($X8,TARIFF_PROFILES!$A:$A,0))) | AH8: =IF($AG8="","",SUMIFS(OPERATING_COEFFS!$C:$C,OPERATING_COEFFS!$A:$A,"DistanceClass",OPERATING_COEFFS!$B:$B,$AG8)) | AJ8: =IF($AI8="","",SUMIFS(OPERATING_COEFFS!$C:$C,OPERATING_COEFFS!$A:$A,"SeasonClass",OPERATING_COEFFS!$B:$B,$AI8)) | AL8: =IF($AK8="","",SUMIFS(OPERATING_COEFFS!$C:$C,OPERATING_COEFFS!$A:$A,"UrgencyClass",OPERATING_COEFFS!$B:$B,$AK8)) | AN8: =IF($AM8="","",INDEX(TAX_MODES!$B:$B,MATCH($AM8,TAX_MODES!$A:$A,0)))
D9: =IF($C9="","",SUMIFS(SITE_COEFFS!$C:$C,SITE_COEFFS!$A:$A,"SoilWorkability",SITE_COEFFS!$B:$B,$C9)) | F9: =IF($E9="","",SUMIFS(SITE_COEFFS!$C:$C,SITE_COEFFS!$A:$A,"SoilMoisture",SITE_COEFFS!$B:$B,$E9)) | H9: =IF($G9="","",SUMIFS(SITE_COEFFS!$C:$C,SITE_COEFFS!$A:$A,"DebrisLevel",SITE_COEFFS!$B:$B,$G9)) | J9: =IF($I9="","",SUMIFS(SITE_COEFFS!$C:$C,SITE_COEFFS!$A:$A,"SlopeClass",SITE_COEFFS!$B:$B,$I9)) | L9: =IF($K9="","",SUMIFS(SITE_COEFFS!$C:$C,SITE_COEFFS!$A:$A,"SurfaceUnevenness",SITE_COEFFS!$B:$B,$K9)) | N9: =IF($M9="","",SUMIFS(SITE_COEFFS!$C:$C,SITE_COEFFS!$A:$A,"AccessClass",SITE_COEFFS!$B:$B,$M9)) | P9: =IF($O9="","",SUMIFS(SITE_COEFFS!$C:$C,SITE_COEFFS!$A:$A,"TurnSpace",SITE_COEFFS!$B:$B,$O9)) | R9: =IF($Q9="","",SUMIFS(SITE_COEFFS!$C:$C,SITE_COEFFS!$A:$A,"ProximityToBuildings",SITE_COEFFS!$B:$B,$Q9)) | T9: =IF($S9="","",SUMIFS(SITE_COEFFS!$C:$C,SITE_COEFFS!$A:$A,"MachineryAllowed",SITE_COEFFS!$B:$B,$S9)) | W9: =IF($V9="","",SUMIFS(SITE_COEFFS!$C:$C,SITE_COEFFS!$A:$A,"GeometryComplexity",SITE_COEFFS!$B:$B,$V9)) | Y9: =IF($X9="","",SUMIFS(TARIFF_PROFILES!$D:$D,TARIFF_PROFILES!$A:$A,$X9)) | Z9: =IF($X9="","",SUMIFS(TARIFF_PROFILES!$E:$E,TARIFF_PROFILES!$A:$A,$X9)) | AA9: =IF($X9="","",SUMIFS(TARIFF_PROFILES!$F:$F,TARIFF_PROFILES!$A:$A,$X9)) | AB9: =IF($X9="","",SUMIFS(TARIFF_PROFILES!$G:$G,TARIFF_PROFILES!$A:$A,$X9)) | AC9: =IF($X9="","",SUMIFS(TARIFF_PROFILES!$H:$H,TARIFF_PROFILES!$A:$A,$X9)) | AD9: =IF($X9="","",INDEX(TARIFF_PROFILES!$J:$J,MATCH($X9,TARIFF_PROFILES!$A:$A,0))) | AE9: =IF($X9="","",INDEX(TARIFF_PROFILES!$K:$K,MATCH($X9,TARIFF_PROFILES!$A:$A,0))) | AH9: =IF($AG9="","",SUMIFS(OPERATING_COEFFS!$C:$C,OPERATING_COEFFS!$A:$A,"DistanceClass",OPERATING_COEFFS!$B:$B,$AG9)) | AJ9: =IF($AI9="","",SUMIFS(OPERATING_COEFFS!$C:$C,OPERATING_COEFFS!$A:$A,"SeasonClass",OPERATING_COEFFS!$B:$B,$AI9)) | AL9: =IF($AK9="","",SUMIFS(OPERATING_COEFFS!$C:$C,OPERATING_COEFFS!$A:$A,"UrgencyClass",OPERATING_COEFFS!$B:$B,$AK9)) | AN9: =IF($AM9="","",INDEX(TAX_MODES!$B:$B,MATCH($AM9,TAX_MODES!$A:$A,0)))
D10: =IF($C10="","",SUMIFS(SITE_COEFFS!$C:$C,SITE_COEFFS!$A:$A,"SoilWorkability",SITE_COEFFS!$B:$B,$C10)) | F10: =IF($E10="","",SUMIFS(SITE_COEFFS!$C:$C,SITE_COEFFS!$A:$A,"SoilMoisture",SITE_COEFFS!$B:$B,$E10)) | H10: =IF($G10="","",SUMIFS(SITE_COEFFS!$C:$C,SITE_COEFFS!$A:$A,"DebrisLevel",SITE_COEFFS!$B:$B,$G10)) | J10: =IF($I10="","",SUMIFS(SITE_COEFFS!$C:$C,SITE_COEFFS!$A:$A,"SlopeClass",SITE_COEFFS!$B:$B,$I10)) | L10: =IF($K10="","",SUMIFS(SITE_COEFFS!$C:$C,SITE_COEFFS!$A:$A,"SurfaceUnevenness",SITE_COEFFS!$B:$B,$K10)) | N10: =IF($M10="","",SUMIFS(SITE_COEFFS!$C:$C,SITE_COEFFS!$A:$A,"AccessClass",SITE_COEFFS!$B:$B,$M10)) | P10: =IF($O10="","",SUMIFS(SITE_COEFFS!$C:$C,SITE_COEFFS!$A:$A,"TurnSpace",SITE_COEFFS!$B:$B,$O10)) | R10: =IF($Q10="","",SUMIFS(SITE_COEFFS!$C:$C,SITE_COEFFS!$A:$A,"ProximityToBuildings",SITE_COEFFS!$B:$B,$Q10)) | T10: =IF($S10="","",SUMIFS(SITE_COEFFS!$C:$C,SITE_COEFFS!$A:$A,"MachineryAllowed",SITE_COEFFS!$B:$B,$S10)) | W10: =IF($V10="","",SUMIFS(SITE_COEFFS!$C:$C,SITE_COEFFS!$A:$A,"GeometryComplexity",SITE_COEFFS!$B:$B,$V10)) | Y10: =IF($X10="","",SUMIFS(TARIFF_PROFILES!$D:$D,TARIFF_PROFILES!$A:$A,$X10)) | Z10: =IF($X10="","",SUMIFS(TARIFF_PROFILES!$E:$E,TARIFF_PROFILES!$A:$A,$X10)) | AA10: =IF($X10="","",SUMIFS(TARIFF_PROFILES!$F:$F,TARIFF_PROFILES!$A:$A,$X10)) | AB10: =IF($X10="","",SUMIFS(TARIFF_PROFILES!$G:$G,TARIFF_PROFILES!$A:$A,$X10)) | AC10: =IF($X10="","",SUMIFS(TARIFF_PROFILES!$H:$H,TARIFF_PROFILES!$A:$A,$X10)) | AD10: =IF($X10="","",INDEX(TARIFF_PROFILES!$J:$J,MATCH($X10,TARIFF_PROFILES!$A:$A,0))) | AE10: =IF($X10="","",INDEX(TARIFF_PROFILES!$K:$K,MATCH($X10,TARIFF_PROFILES!$A:$A,0))) | AH10: =IF($AG10="","",SUMIFS(OPERATING_COEFFS!$C:$C,OPERATING_COEFFS!$A:$A,"DistanceClass",OPERATING_COEFFS!$B:$B,$AG10)) | AJ10: =IF($AI10="","",SUMIFS(OPERATING_COEFFS!$C:$C,OPERATING_COEFFS!$A:$A,"SeasonClass",OPERATING_COEFFS!$B:$B,$AI10)) | AL10: =IF($AK10="","",SUMIFS(OPERATING_COEFFS!$C:$C,OPERATING_COEFFS!$A:$A,"UrgencyClass",OPERATING_COEFFS!$B:$B,$AK10)) | AN10: =IF($AM10="","",INDEX(TAX_MODES!$B:$B,MATCH($AM10,TAX_MODES!$A:$A,0)))
D11: =IF($C11="","",SUMIFS(SITE_COEFFS!$C:$C,SITE_COEFFS!$A:$A,"SoilWorkability",SITE_COEFFS!$B:$B,$C11)) | F11: =IF($E11="","",SUMIFS(SITE_COEFFS!$C:$C,SITE_COEFFS!$A:$A,"SoilMoisture",SITE_COEFFS!$B:$B,$E11)) | H11: =IF($G11="","",SUMIFS(SITE_COEFFS!$C:$C,SITE_COEFFS!$A:$A,"DebrisLevel",SITE_COEFFS!$B:$B,$G11)) | J11: =IF($I11="","",SUMIFS(SITE_COEFFS!$C:$C,SITE_COEFFS!$A:$A,"SlopeClass",SITE_COEFFS!$B:$B,$I11)) | L11: =IF($K11="","",SUMIFS(SITE_COEFFS!$C:$C,SITE_COEFFS!$A:$A,"SurfaceUnevenness",SITE_COEFFS!$B:$B,$K11)) | N11: =IF($M11="","",SUMIFS(SITE_COEFFS!$C:$C,SITE_COEFFS!$A:$A,"AccessClass",SITE_COEFFS!$B:$B,$M11)) | P11: =IF($O11="","",SUMIFS(SITE_COEFFS!$C:$C,SITE_COEFFS!$A:$A,"TurnSpace",SITE_COEFFS!$B:$B,$O11)) | R11: =IF($Q11="","",SUMIFS(SITE_COEFFS!$C:$C,SITE_COEFFS!$A:$A,"ProximityToBuildings",SITE_COEFFS!$B:$B,$Q11)) | T11: =IF($S11="","",SUMIFS(SITE_COEFFS!$C:$C,SITE_COEFFS!$A:$A,"MachineryAllowed",SITE_COEFFS!$B:$B,$S11)) | W11: =IF($V11="","",SUMIFS(SITE_COEFFS!$C:$C,SITE_COEFFS!$A:$A,"GeometryComplexity",SITE_COEFFS!$B:$B,$V11)) | Y11: =IF($X11="","",SUMIFS(TARIFF_PROFILES!$D:$D,TARIFF_PROFILES!$A:$A,$X11)) | Z11: =IF($X11="","",SUMIFS(TARIFF_PROFILES!$E:$E,TARIFF_PROFILES!$A:$A,$X11)) | AA11: =IF($X11="","",SUMIFS(TARIFF_PROFILES!$F:$F,TARIFF_PROFILES!$A:$A,$X11)) | AB11: =IF($X11="","",SUMIFS(TARIFF_PROFILES!$G:$G,TARIFF_PROFILES!$A:$A,$X11)) | AC11: =IF($X11="","",SUMIFS(TARIFF_PROFILES!$H:$H,TARIFF_PROFILES!$A:$A,$X11)) | AD11: =IF($X11="","",INDEX(TARIFF_PROFILES!$J:$J,MATCH($X11,TARIFF_PROFILES!$A:$A,0))) | AE11: =IF($X11="","",INDEX(TARIFF_PROFILES!$K:$K,MATCH($X11,TARIFF_PROFILES!$A:$A,0))) | AH11: =IF($AG11="","",SUMIFS(OPERATING_COEFFS!$C:$C,OPERATING_COEFFS!$A:$A,"DistanceClass",OPERATING_COEFFS!$B:$B,$AG11)) | AJ11: =IF($AI11="","",SUMIFS(OPERATING_COEFFS!$C:$C,OPERATING_COEFFS!$A:$A,"SeasonClass",OPERATING_COEFFS!$B:$B,$AI11)) | AL11: =IF($AK11="","",SUMIFS(OPERATING_COEFFS!$C:$C,OPERATING_COEFFS!$A:$A,"UrgencyClass",OPERATING_COEFFS!$B:$B,$AK11)) | AN11: =IF($AM11="","",INDEX(TAX_MODES!$B:$B,MATCH($AM11,TAX_MODES!$A:$A,0)))
D12: =IF($C12="","",SUMIFS(SITE_COEFFS!$C:$C,SITE_COEFFS!$A:$A,"SoilWorkability",SITE_COEFFS!$B:$B,$C12)) | F12: =IF($E12="","",SUMIFS(SITE_COEFFS!$C:$C,SITE_COEFFS!$A:$A,"SoilMoisture",SITE_COEFFS!$B:$B,$E12)) | H12: =IF($G12="","",SUMIFS(SITE_COEFFS!$C:$C,SITE_COEFFS!$A:$A,"DebrisLevel",SITE_COEFFS!$B:$B,$G12)) | J12: =IF($I12="","",SUMIFS(SITE_COEFFS!$C:$C,SITE_COEFFS!$A:$A,"SlopeClass",SITE_COEFFS!$B:$B,$I12)) | L12: =IF($K12="","",SUMIFS(SITE_COEFFS!$C:$C,SITE_COEFFS!$A:$A,"SurfaceUnevenness",SITE_COEFFS!$B:$B,$K12)) | N12: =IF($M12="","",SUMIFS(SITE_COEFFS!$C:$C,SITE_COEFFS!$A:$A,"AccessClass",SITE_COEFFS!$B:$B,$M12)) | P12: =IF($O12="","",SUMIFS(SITE_COEFFS!$C:$C,SITE_COEFFS!$A:$A,"TurnSpace",SITE_COEFFS!$B:$B,$O12)) | R12: =IF($Q12="","",SUMIFS(SITE_COEFFS!$C:$C,SITE_COEFFS!$A:$A,"ProximityToBuildings",SITE_COEFFS!$B:$B,$Q12)) | T12: =IF($S12="","",SUMIFS(SITE_COEFFS!$C:$C,SITE_COEFFS!$A:$A,"MachineryAllowed",SITE_COEFFS!$B:$B,$S12)) | W12: =IF($V12="","",SUMIFS(SITE_COEFFS!$C:$C,SITE_COEFFS!$A:$A,"GeometryComplexity",SITE_COEFFS!$B:$B,$V12)) | Y12: =IF($X12="","",SUMIFS(TARIFF_PROFILES!$D:$D,TARIFF_PROFILES!$A:$A,$X12)) | Z12: =IF($X12="","",SUMIFS(TARIFF_PROFILES!$E:$E,TARIFF_PROFILES!$A:$A,$X12)) | AA12: =IF($X12="","",SUMIFS(TARIFF_PROFILES!$F:$F,TARIFF_PROFILES!$A:$A,$X12)) | AB12: =IF($X12="","",SUMIFS(TARIFF_PROFILES!$G:$G,TARIFF_PROFILES!$A:$A,$X12)) | AC12: =IF($X12="","",SUMIFS(TARIFF_PROFILES!$H:$H,TARIFF_PROFILES!$A:$A,$X12)) | AD12: =IF($X12="","",INDEX(TARIFF_PROFILES!$J:$J,MATCH($X12,TARIFF_PROFILES!$A:$A,0))) | AE12: =IF($X12="","",INDEX(TARIFF_PROFILES!$K:$K,MATCH($X12,TARIFF_PROFILES!$A:$A,0))) | AH12: =IF($AG12="","",SUMIFS(OPERATING_COEFFS!$C:$C,OPERATING_COEFFS!$A:$A,"DistanceClass",OPERATING_COEFFS!$B:$B,$AG12)) | AJ12: =IF($AI12="","",SUMIFS(OPERATING_COEFFS!$C:$C,OPERATING_COEFFS!$A:$A,"SeasonClass",OPERATING_COEFFS!$B:$B,$AI12)) | AL12: =IF($AK12="","",SUMIFS(OPERATING_COEFFS!$C:$C,OPERATING_COEFFS!$A:$A,"UrgencyClass",OPERATING_COEFFS!$B:$B,$AK12)) | AN12: =IF($AM12="","",INDEX(TAX_MODES!$B:$B,MATCH($AM12,TAX_MODES!$A:$A,0)))
D13: =IF($C13="","",SUMIFS(SITE_COEFFS!$C:$C,SITE_COEFFS!$A:$A,"SoilWorkability",SITE_COEFFS!$B:$B,$C13)) | F13: =IF($E13="","",SUMIFS(SITE_COEFFS!$C:$C,SITE_COEFFS!$A:$A,"SoilMoisture",SITE_COEFFS!$B:$B,$E13)) | H13: =IF($G13="","",SUMIFS(SITE_COEFFS!$C:$C,SITE_COEFFS!$A:$A,"DebrisLevel",SITE_COEFFS!$B:$B,$G13)) | J13: =IF($I13="","",SUMIFS(SITE_COEFFS!$C:$C,SITE_COEFFS!$A:$A,"SlopeClass",SITE_COEFFS!$B:$B,$I13)) | L13: =IF($K13="","",SUMIFS(SITE_COEFFS!$C:$C,SITE_COEFFS!$A:$A,"SurfaceUnevenness",SITE_COEFFS!$B:$B,$K13)) | N13: =IF($M13="","",SUMIFS(SITE_COEFFS!$C:$C,SITE_COEFFS!$A:$A,"AccessClass",SITE_COEFFS!$B:$B,$M13)) | P13: =IF($O13="","",SUMIFS(SITE_COEFFS!$C:$C,SITE_COEFFS!$A:$A,"TurnSpace",SITE_COEFFS!$B:$B,$O13)) | R13: =IF($Q13="","",SUMIFS(SITE_COEFFS!$C:$C,SITE_COEFFS!$A:$A,"ProximityToBuildings",SITE_COEFFS!$B:$B,$Q13)) | T13: =IF($S13="","",SUMIFS(SITE_COEFFS!$C:$C,SITE_COEFFS!$A:$A,"MachineryAllowed",SITE_COEFFS!$B:$B,$S13)) | W13: =IF($V13="","",SUMIFS(SITE_COEFFS!$C:$C,SITE_COEFFS!$A:$A,"GeometryComplexity",SITE_COEFFS!$B:$B,$V13)) | Y13: =IF($X13="","",SUMIFS(TARIFF_PROFILES!$D:$D,TARIFF_PROFILES!$A:$A,$X13)) | Z13: =IF($X13="","",SUMIFS(TARIFF_PROFILES!$E:$E,TARIFF_PROFILES!$A:$A,$X13)) | AA13: =IF($X13="","",SUMIFS(TARIFF_PROFILES!$F:$F,TARIFF_PROFILES!$A:$A,$X13)) | AB13: =IF($X13="","",SUMIFS(TARIFF_PROFILES!$G:$G,TARIFF_PROFILES!$A:$A,$X13)) | AC13: =IF($X13="","",SUMIFS(TARIFF_PROFILES!$H:$H,TARIFF_PROFILES!$A:$A,$X13)) | AD13: =IF($X13="","",INDEX(TARIFF_PROFILES!$J:$J,MATCH($X13,TARIFF_PROFILES!$A:$A,0))) | AE13: =IF($X13="","",INDEX(TARIFF_PROFILES!$K:$K,MATCH($X13,TARIFF_PROFILES!$A:$A,0))) | AH13: =IF($AG13="","",SUMIFS(OPERATING_COEFFS!$C:$C,OPERATING_COEFFS!$A:$A,"DistanceClass",OPERATING_COEFFS!$B:$B,$AG13)) | AJ13: =IF($AI13="","",SUMIFS(OPERATING_COEFFS!$C:$C,OPERATING_COEFFS!$A:$A,"SeasonClass",OPERATING_COEFFS!$B:$B,$AI13)) | AL13: =IF($AK13="","",SUMIFS(OPERATING_COEFFS!$C:$C,OPERATING_COEFFS!$A:$A,"UrgencyClass",OPERATING_COEFFS!$B:$B,$AK13)) | AN13: =IF($AM13="","",INDEX(TAX_MODES!$B:$B,MATCH($AM13,TAX_MODES!$A:$A,0)))
D14: =IF($C14="","",SUMIFS(SITE_COEFFS!$C:$C,SITE_COEFFS!$A:$A,"SoilWorkability",SITE_COEFFS!$B:$B,$C14)) | F14: =IF($E14="","",SUMIFS(SITE_COEFFS!$C:$C,SITE_COEFFS!$A:$A,"SoilMoisture",SITE_COEFFS!$B:$B,$E14)) | H14: =IF($G14="","",SUMIFS(SITE_COEFFS!$C:$C,SITE_COEFFS!$A:$A,"DebrisLevel",SITE_COEFFS!$B:$B,$G14)) | J14: =IF($I14="","",SUMIFS(SITE_COEFFS!$C:$C,SITE_COEFFS!$A:$A,"SlopeClass",SITE_COEFFS!$B:$B,$I14)) | L14: =IF($K14="","",SUMIFS(SITE_COEFFS!$C:$C,SITE_COEFFS!$A:$A,"SurfaceUnevenness",SITE_COEFFS!$B:$B,$K14)) | N14: =IF($M14="","",SUMIFS(SITE_COEFFS!$C:$C,SITE_COEFFS!$A:$A,"AccessClass",SITE_COEFFS!$B:$B,$M14)) | P14: =IF($O14="","",SUMIFS(SITE_COEFFS!$C:$C,SITE_COEFFS!$A:$A,"TurnSpace",SITE_COEFFS!$B:$B,$O14)) | R14: =IF($Q14="","",SUMIFS(SITE_COEFFS!$C:$C,SITE_COEFFS!$A:$A,"ProximityToBuildings",SITE_COEFFS!$B:$B,$Q14)) | T14: =IF($S14="","",SUMIFS(SITE_COEFFS!$C:$C,SITE_COEFFS!$A:$A,"MachineryAllowed",SITE_COEFFS!$B:$B,$S14)) | W14: =IF($V14="","",SUMIFS(SITE_COEFFS!$C:$C,SITE_COEFFS!$A:$A,"GeometryComplexity",SITE_COEFFS!$B:$B,$V14)) | Y14: =IF($X14="","",SUMIFS(TARIFF_PROFILES!$D:$D,TARIFF_PROFILES!$A:$A,$X14)) | Z14: =IF($X14="","",SUMIFS(TARIFF_PROFILES!$E:$E,TARIFF_PROFILES!$A:$A,$X14)) | AA14: =IF($X14="","",SUMIFS(TARIFF_PROFILES!$F:$F,TARIFF_PROFILES!$A:$A,$X14)) | AB14: =IF($X14="","",SUMIFS(TARIFF_PROFILES!$G:$G,TARIFF_PROFILES!$A:$A,$X14)) | AC14: =IF($X14="","",SUMIFS(TARIFF_PROFILES!$H:$H,TARIFF_PROFILES!$A:$A,$X14)) | AD14: =IF($X14="","",INDEX(TARIFF_PROFILES!$J:$J,MATCH($X14,TARIFF_PROFILES!$A:$A,0))) | AE14: =IF($X14="","",INDEX(TARIFF_PROFILES!$K:$K,MATCH($X14,TARIFF_PROFILES!$A:$A,0))) | AH14: =IF($AG14="","",SUMIFS(OPERATING_COEFFS!$C:$C,OPERATING_COEFFS!$A:$A,"DistanceClass",OPERATING_COEFFS!$B:$B,$AG14)) | AJ14: =IF($AI14="","",SUMIFS(OPERATING_COEFFS!$C:$C,OPERATING_COEFFS!$A:$A,"SeasonClass",OPERATING_COEFFS!$B:$B,$AI14)) | AL14: =IF($AK14="","",SUMIFS(OPERATING_COEFFS!$C:$C,OPERATING_COEFFS!$A:$A,"UrgencyClass",OPERATING_COEFFS!$B:$B,$AK14)) | AN14: =IF($AM14="","",INDEX(TAX_MODES!$B:$B,MATCH($AM14,TAX_MODES!$A:$A,0)))
D15: =IF($C15="","",SUMIFS(SITE_COEFFS!$C:$C,SITE_COEFFS!$A:$A,"SoilWorkability",SITE_COEFFS!$B:$B,$C15)) | F15: =IF($E15="","",SUMIFS(SITE_COEFFS!$C:$C,SITE_COEFFS!$A:$A,"SoilMoisture",SITE_COEFFS!$B:$B,$E15)) | H15: =IF($G15="","",SUMIFS(SITE_COEFFS!$C:$C,SITE_COEFFS!$A:$A,"DebrisLevel",SITE_COEFFS!$B:$B,$G15)) | J15: =IF($I15="","",SUMIFS(SITE_COEFFS!$C:$C,SITE_COEFFS!$A:$A,"SlopeClass",SITE_COEFFS!$B:$B,$I15)) | L15: =IF($K15="","",SUMIFS(SITE_COEFFS!$C:$C,SITE_COEFFS!$A:$A,"SurfaceUnevenness",SITE_COEFFS!$B:$B,$K15)) | N15: =IF($M15="","",SUMIFS(SITE_COEFFS!$C:$C,SITE_COEFFS!$A:$A,"AccessClass",SITE_COEFFS!$B:$B,$M15)) | P15: =IF($O15="","",SUMIFS(SITE_COEFFS!$C:$C,SITE_COEFFS!$A:$A,"TurnSpace",SITE_COEFFS!$B:$B,$O15)) | R15: =IF($Q15="","",SUMIFS(SITE_COEFFS!$C:$C,SITE_COEFFS!$A:$A,"ProximityToBuildings",SITE_COEFFS!$B:$B,$Q15)) | T15: =IF($S15="","",SUMIFS(SITE_COEFFS!$C:$C,SITE_COEFFS!$A:$A,"MachineryAllowed",SITE_COEFFS!$B:$B,$S15)) | W15: =IF($V15="","",SUMIFS(SITE_COEFFS!$C:$C,SITE_COEFFS!$A:$A,"GeometryComplexity",SITE_COEFFS!$B:$B,$V15)) | Y15: =IF($X15="","",SUMIFS(TARIFF_PROFILES!$D:$D,TARIFF_PROFILES!$A:$A,$X15)) | Z15: =IF($X15="","",SUMIFS(TARIFF_PROFILES!$E:$E,TARIFF_PROFILES!$A:$A,$X15)) | AA15: =IF($X15="","",SUMIFS(TARIFF_PROFILES!$F:$F,TARIFF_PROFILES!$A:$A,$X15)) | AB15: =IF($X15="","",SUMIFS(TARIFF_PROFILES!$G:$G,TARIFF_PROFILES!$A:$A,$X15)) | AC15: =IF($X15="","",SUMIFS(TARIFF_PROFILES!$H:$H,TARIFF_PROFILES!$A:$A,$X15)) | AD15: =IF($X15="","",INDEX(TARIFF_PROFILES!$J:$J,MATCH($X15,TARIFF_PROFILES!$A:$A,0))) | AE15: =IF($X15="","",INDEX(TARIFF_PROFILES!$K:$K,MATCH($X15,TARIFF_PROFILES!$A:$A,0))) | AH15: =IF($AG15="","",SUMIFS(OPERATING_COEFFS!$C:$C,OPERATING_COEFFS!$A:$A,"DistanceClass",OPERATING_COEFFS!$B:$B,$AG15)) | AJ15: =IF($AI15="","",SUMIFS(OPERATING_COEFFS!$C:$C,OPERATING_COEFFS!$A:$A,"SeasonClass",OPERATING_COEFFS!$B:$B,$AI15)) | AL15: =IF($AK15="","",SUMIFS(OPERATING_COEFFS!$C:$C,OPERATING_COEFFS!$A:$A,"UrgencyClass",OPERATING_COEFFS!$B:$B,$AK15)) | AN15: =IF($AM15="","",INDEX(TAX_MODES!$B:$B,MATCH($AM15,TAX_MODES!$A:$A,0)))
... D150: =IF($C150="","",SUMIFS(SITE_COEFFS!$C:$C,SITE_COEFFS!$A:$A,"SoilWorkability",SITE_COEFFS!$B:$B,$C150)) | F150: =IF($E150="","",SUMIFS(SITE_COEFFS!$C:$C,SITE_COEFFS!$A:$A,"SoilMoisture",SITE_COEFFS!$B:$B,$E150)) | H150: =IF($G150="","",SUMIFS(SITE_COEFFS!$C:$C,SITE_COEFFS!$A:$A,"DebrisLevel",SITE_COEFFS!$B:$B,$G150)) | J150: =IF($I150="","",SUMIFS(SITE_COEFFS!$C:$C,SITE_COEFFS!$A:$A,"SlopeClass",SITE_COEFFS!$B:$B,$I150)) | L150: =IF($K150="","",SUMIFS(SITE_COEFFS!$C:$C,SITE_COEFFS!$A:$A,"SurfaceUnevenness",SITE_COEFFS!$B:$B,$K150)) | N150: =IF($M150="","",SUMIFS(SITE_COEFFS!$C:$C,SITE_COEFFS!$A:$A,"AccessClass",SITE_COEFFS!$B:$B,$M150)) | P150: =IF($O150="","",SUMIFS(SITE_COEFFS!$C:$C,SITE_COEFFS!$A:$A,"TurnSpace",SITE_COEFFS!$B:$B,$O150)) | R150: =IF($Q150="","",SUMIFS(SITE_COEFFS!$C:$C,SITE_COEFFS!$A:$A,"ProximityToBuildings",SITE_COEFFS!$B:$B,$Q150)) | T150: =IF($S150="","",SUMIFS(SITE_COEFFS!$C:$C,SITE_COEFFS!$A:$A,"MachineryAllowed",SITE_COEFFS!$B:$B,$S150)) | W150: =IF($V150="","",SUMIFS(SITE_COEFFS!$C:$C,SITE_COEFFS!$A:$A,"GeometryComplexity",SITE_COEFFS!$B:$B,$V150)) | Y150: =IF($X150="","",SUMIFS(TARIFF_PROFILES!$D:$D,TARIFF_PROFILES!$A:$A,$X150)) | Z150: =IF($X150="","",SUMIFS(TARIFF_PROFILES!$E:$E,TARIFF_PROFILES!$A:$A,$X150)) | AA150: =IF($X150="","",SUMIFS(TARIFF_PROFILES!$F:$F,TARIFF_PROFILES!$A:$A,$X150)) | AB150: =IF($X150="","",SUMIFS(TARIFF_PROFILES!$G:$G,TARIFF_PROFILES!$A:$A,$X150)) | AC150: =IF($X150="","",SUMIFS(TARIFF_PROFILES!$H:$H,TARIFF_PROFILES!$A:$A,$X150)) | AD150: =IF($X150="","",INDEX(TARIFF_PROFILES!$J:$J,MATCH($X150,TARIFF_PROFILES!$A:$A,0))) | AE150: =IF($X150="","",INDEX(TARIFF_PROFILES!$K:$K,MATCH($X150,TARIFF_PROFILES!$A:$A,0))) | AH150: =IF($AG150="","",SUMIFS(OPERATING_COEFFS!$C:$C,OPERATING_COEFFS!$A:$A,"DistanceClass",OPERATING_COEFFS!$B:$B,$AG150)) | AJ150: =IF($AI150="","",SUMIFS(OPERATING_COEFFS!$C:$C,OPERATING_COEFFS!$A:$A,"SeasonClass",OPERATING_COEFFS!$B:$B,$AI150)) | AL150: =IF($AK150="","",SUMIFS(OPERATING_COEFFS!$C:$C,OPERATING_COEFFS!$A:$A,"UrgencyClass",OPERATING_COEFFS!$B:$B,$AK150)) | AN150: =IF($AM150="","",INDEX(TAX_MODES!$B:$B,MATCH($AM150,TAX_MODES!$A:$A,0)))
Y151: =IF($X151="","",SUMIFS(TARIFF_PROFILES!$D:$D,TARIFF_PROFILES!$A:$A,$X151)) | Z151: =IF($X151="","",SUMIFS(TARIFF_PROFILES!$E:$E,TARIFF_PROFILES!$A:$A,$X151)) | AA151: =IF($X151="","",SUMIFS(TARIFF_PROFILES!$F:$F,TARIFF_PROFILES!$A:$A,$X151)) | AB151: =IF($X151="","",SUMIFS(TARIFF_PROFILES!$G:$G,TARIFF_PROFILES!$A:$A,$X151)) | AC151: =IF($X151="","",SUMIFS(TARIFF_PROFILES!$H:$H,TARIFF_PROFILES!$A:$A,$X151)) | AD151: =IF($X151="","",INDEX(TARIFF_PROFILES!$J:$J,MATCH($X151,TARIFF_PROFILES!$A:$A,0))) | AE151: =IF($X151="","",INDEX(TARIFF_PROFILES!$K:$K,MATCH($X151,TARIFF_PROFILES!$A:$A,0))) | AH151: =IF($AG151="","",SUMIFS(OPERATING_COEFFS!$C:$C,OPERATING_COEFFS!$A:$A,"DistanceClass",OPERATING_COEFFS!$B:$B,$AG151)) | AJ151: =IF($AI151="","",SUMIFS(OPERATING_COEFFS!$C:$C,OPERATING_COEFFS!$A:$A,"SeasonClass",OPERATING_COEFFS!$B:$B,$AI151)) | AL151: =IF($AK151="","",SUMIFS(OPERATING_COEFFS!$C:$C,OPERATING_COEFFS!$A:$A,"UrgencyClass",OPERATING_COEFFS!$B:$B,$AK151)) | AN151: =IF($AM151="","",INDEX(TAX_MODES!$B:$B,MATCH($AM151,TAX_MODES!$A:$A,0)))
Y152: =IF($X152="","",SUMIFS(TARIFF_PROFILES!$D:$D,TARIFF_PROFILES!$A:$A,$X152)) | Z152: =IF($X152="","",SUMIFS(TARIFF_PROFILES!$E:$E,TARIFF_PROFILES!$A:$A,$X152)) | AA152: =IF($X152="","",SUMIFS(TARIFF_PROFILES!$F:$F,TARIFF_PROFILES!$A:$A,$X152)) | AB152: =IF($X152="","",SUMIFS(TARIFF_PROFILES!$G:$G,TARIFF_PROFILES!$A:$A,$X152)) | AC152: =IF($X152="","",SUMIFS(TARIFF_PROFILES!$H:$H,TARIFF_PROFILES!$A:$A,$X152)) | AD152: =IF($X152="","",INDEX(TARIFF_PROFILES!$J:$J,MATCH($X152,TARIFF_PROFILES!$A:$A,0))) | AE152: =IF($X152="","",INDEX(TARIFF_PROFILES!$K:$K,MATCH($X152,TARIFF_PROFILES!$A:$A,0))) | AH152: =IF($AG152="","",SUMIFS(OPERATING_COEFFS!$C:$C,OPERATING_COEFFS!$A:$A,"DistanceClass",OPERATING_COEFFS!$B:$B,$AG152)) | AJ152: =IF($AI152="","",SUMIFS(OPERATING_COEFFS!$C:$C,OPERATING_COEFFS!$A:$A,"SeasonClass",OPERATING_COEFFS!$B:$B,$AI152)) | AL152: =IF($AK152="","",SUMIFS(OPERATING_COEFFS!$C:$C,OPERATING_COEFFS!$A:$A,"UrgencyClass",OPERATING_COEFFS!$B:$B,$AK152)) | AN152: =IF($AM152="","",INDEX(TAX_MODES!$B:$B,MATCH($AM152,TAX_MODES!$A:$A,0)))
Y153: =IF($X153="","",SUMIFS(TARIFF_PROFILES!$D:$D,TARIFF_PROFILES!$A:$A,$X153)) | Z153: =IF($X153="","",SUMIFS(TARIFF_PROFILES!$E:$E,TARIFF_PROFILES!$A:$A,$X153)) | AA153: =IF($X153="","",SUMIFS(TARIFF_PROFILES!$F:$F,TARIFF_PROFILES!$A:$A,$X153)) | AB153: =IF($X153="","",SUMIFS(TARIFF_PROFILES!$G:$G,TARIFF_PROFILES!$A:$A,$X153)) | AC153: =IF($X153="","",SUMIFS(TARIFF_PROFILES!$H:$H,TARIFF_PROFILES!$A:$A,$X153)) | AD153: =IF($X153="","",INDEX(TARIFF_PROFILES!$J:$J,MATCH($X153,TARIFF_PROFILES!$A:$A,0))) | AE153: =IF($X153="","",INDEX(TARIFF_PROFILES!$K:$K,MATCH($X153,TARIFF_PROFILES!$A:$A,0))) | AH153: =IF($AG153="","",SUMIFS(OPERATING_COEFFS!$C:$C,OPERATING_COEFFS!$A:$A,"DistanceClass",OPERATING_COEFFS!$B:$B,$AG153)) | AJ153: =IF($AI153="","",SUMIFS(OPERATING_COEFFS!$C:$C,OPERATING_COEFFS!$A:$A,"SeasonClass",OPERATING_COEFFS!$B:$B,$AI153)) | AL153: =IF($AK153="","",SUMIFS(OPERATING_COEFFS!$C:$C,OPERATING_COEFFS!$A:$A,"UrgencyClass",OPERATING_COEFFS!$B:$B,$AK153)) | AN153: =IF($AM153="","",INDEX(TAX_MODES!$B:$B,MATCH($AM153,TAX_MODES!$A:$A,0)))
