Workbook

Sheet Расчет
A1: print_flag | B1: section_no | C1: section_name | D1: subsection_name | E1: row_type | F1: sort_order | G1: item_name | H1: unit | I1: qty | J1: unit_price | K1: works_amount | L1: materials_amount | M1: note
A2: да | B2: 1 | C2: Подготовительные земельные работы | E2: work | F2: 1 | G2: Разметка и нивелировка площадей, задание вертикальных уровней и уклона (геодезическая разбивка) | H2: м.кв. | I2: 2540 | J2: 100 | K2: =IF(OR(E2="work",E2="section14_item"),I2*J2,0) | L2: =IF(E2="material",I2*J2,IF(E2="section15_percent",I2/100*(SUMPRODUCT((E$2:E$5000="work")*(B$2:B$5000<>"14")*K$2:K$5000)+SUMPRODUCT((E$2:E$5000="material")*(B$2:B$5000<>"14")*L$2:L$5000)),IF(E2="section15_manual",J2,0)))
A3: да | B3: 1 | C3: Подготовительные земельные работы | E3: work | F3: 2 | G3: Выемка и перемещение грунта и щебня существующего основания для устройства мощения | H3: м.куб. | I3: 110 | J3: 100 | K3: =IF(OR(E3="work",E3="section14_item"),I3*J3,0) | L3: =IF(E3="material",I3*J3,IF(E3="section15_percent",I3/100*(SUMPRODUCT((E$2:E$5000="work")*(B$2:B$5000<>"14")*K$2:K$5000)+SUMPRODUCT((E$2:E$5000="material")*(B$2:B$5000<>"14")*L$2:L$5000)),IF(E3="section15_manual",J3,0)))
A4: да | B4: 1 | C4: Подготовительные земельные работы | E4: work | F4: 3 | G4: Выемка и перемещение грунта для устройства ливневой и дренажной систем | H4: м.куб. | I4: 21 | J4: 100 | K4: =IF(OR(E4="work",E4="section14_item"),I4*J4,0) | L4: =IF(E4="material",I4*J4,IF(E4="section15_percent",I4/100*(SUMPRODUCT((E$2:E$5000="work")*(B$2:B$5000<>"14")*K$2:K$5000)+SUMPRODUCT((E$2:E$5000="material")*(B$2:B$5000<>"14")*L$2:L$5000)),IF(E4="section15_manual",J4,0)))
A5: да | B5: 1 | C5: Подготовительные земельные работы | E5: work | F5: 4 | G5: Обратная засыпка песком после устройства ливневой системы | H5: м.куб. | I5: 12 | J5: 100 | K5: =IF(OR(E5="work",E5="section14_item"),I5*J5,0) | L5: =IF(E5="material",I5*J5,IF(E5="section15_percent",I5/100*(SUMPRODUCT((E$2:E$5000="work")*(B$2:B$5000<>"14")*K$2:K$5000)+SUMPRODUCT((E$2:E$5000="material")*(B$2:B$5000<>"14")*L$2:L$5000)),IF(E5="section15_manual",J5,0)))
A6: да | B6: 1 | C6: Подготовительные земельные работы | E6: material | F6: 5 | G6: Песок намывной (самосвал 20м3) | H6: м.куб. | I6: 13.953488 | J6: 100 | K6: =IF(OR(E6="work",E6="section14_item"),I6*J6,0) | L6: =IF(E6="material",I6*J6,IF(E6="section15_percent",I6/100*(SUMPRODUCT((E$2:E$5000="work")*(B$2:B$5000<>"14")*K$2:K$5000)+SUMPRODUCT((E$2:E$5000="material")*(B$2:B$5000<>"14")*L$2:L$5000)),IF(E6="section15_manual",J6,0))) | M6: 10м3 - 1650р/м3
A7: да | B7: 1 | C7: Подготовительные земельные работы | E7: work | F7: 6 | G7: Разборка существующего покрытия | H7: м.кв. | I7: 250 | J7: 100 | K7: =IF(OR(E7="work",E7="section14_item"),I7*J7,0) | L7: =IF(E7="material",I7*J7,IF(E7="section15_percent",I7/100*(SUMPRODUCT((E$2:E$5000="work")*(B$2:B$5000<>"14")*K$2:K$5000)+SUMPRODUCT((E$2:E$5000="material")*(B$2:B$5000<>"14")*L$2:L$5000)),IF(E7="section15_manual",J7,0)))
A8: да | B8: 1 | C8: Подготовительные земельные работы | E8: work | F8: 7 | G8: Погрузка грунта и мусора и вывоз | H8: м.куб. | I8: 131 | K8: =IF(OR(E8="work",E8="section14_item"),I8*J8,0) | L8: =IF(E8="material",I8*J8,IF(E8="section15_percent",I8/100*(SUMPRODUCT((E$2:E$5000="work")*(B$2:B$5000<>"14")*K$2:K$5000)+SUMPRODUCT((E$2:E$5000="material")*(B$2:B$5000<>"14")*L$2:L$5000)),IF(E8="section15_manual",J8,0)))
A9: да | B9: 1 | C9: Подготовительные земельные работы | E9: subsection | F9: 8 | G9: Нижняя зона участка | K9: =IF(OR(E9="work",E9="section14_item"),I9*J9,0) | L9: =IF(E9="material",I9*J9,IF(E9="section15_percent",I9/100*(SUMPRODUCT((E$2:E$5000="work")*(B$2:B$5000<>"14")*K$2:K$5000)+SUMPRODUCT((E$2:E$5000="material")*(B$2:B$5000<>"14")*L$2:L$5000)),IF(E9="section15_manual",J9,0)))
A10: да | B10: 1 | C10: Подготовительные земельные работы | D10: Нижняя зона участка | E10: work | F10: 9 | G10: Снятие верхнего слоя покрова | H10: м.кв. | I10: 820 | J10: 100 | K10: =IF(OR(E10="work",E10="section14_item"),I10*J10,0) | L10: =IF(E10="material",I10*J10,IF(E10="section15_percent",I10/100*(SUMPRODUCT((E$2:E$5000="work")*(B$2:B$5000<>"14")*K$2:K$5000)+SUMPRODUCT((E$2:E$5000="material")*(B$2:B$5000<>"14")*L$2:L$5000)),IF(E10="section15_manual",J10,0)))
A11: да | B11: 1 | C11: Подготовительные земельные работы | D11: Нижняя зона участка | E11: work | F11: 10 | G11: Перемещение сыпучих материалов на расстояние до 50м вручную (склон) с коэффициентом сложности | H11: м.куб. | I11: 25 | J11: 100 | K11: =IF(OR(E11="work",E11="section14_item"),I11*J11,0) | L11: =IF(E11="material",I11*J11,IF(E11="section15_percent",I11/100*(SUMPRODUCT((E$2:E$5000="work")*(B$2:B$5000<>"14")*K$2:K$5000)+SUMPRODUCT((E$2:E$5000="material")*(B$2:B$5000<>"14")*L$2:L$5000)),IF(E11="section15_manual",J11,0)))
A12: да | B12: 1 | C12: Подготовительные земельные работы | D12: Нижняя зона участка | E12: work | F12: 11 | G12: Погрузка грунта и мусора и вывоз | H12: м.куб. | I12: 82 | K12: =IF(OR(E12="work",E12="section14_item"),I12*J12,0) | L12: =IF(E12="material",I12*J12,IF(E12="section15_percent",I12/100*(SUMPRODUCT((E$2:E$5000="work")*(B$2:B$5000<>"14")*K$2:K$5000)+SUMPRODUCT((E$2:E$5000="material")*(B$2:B$5000<>"14")*L$2:L$5000)),IF(E12="section15_manual",J12,0)))
A13: да | B13: 1 | C13: Подготовительные земельные работы | D13: Нижняя зона участка | E13: work | F13: 12 | G13: Вертикальная планировка | H13: м.куб. | I13: 70 | J13: 100 | K13: =IF(OR(E13="work",E13="section14_item"),I13*J13,0) | L13: =IF(E13="material",I13*J13,IF(E13="section15_percent",I13/100*(SUMPRODUCT((E$2:E$5000="work")*(B$2:B$5000<>"14")*K$2:K$5000)+SUMPRODUCT((E$2:E$5000="material")*(B$2:B$5000<>"14")*L$2:L$5000)),IF(E13="section15_manual",J13,0)))
A14: да | B14: 1 | C14: Подготовительные земельные работы | E14: subsection | F14: 13 | G14: Бассейн | K14: =IF(OR(E14="work",E14="section14_item"),I14*J14,0) | L14: =IF(E14="material",I14*J14,IF(E14="section15_percent",I14/100*(SUMPRODUCT((E$2:E$5000="work")*(B$2:B$5000<>"14")*K$2:K$5000)+SUMPRODUCT((E$2:E$5000="material")*(B$2:B$5000<>"14")*L$2:L$5000)),IF(E14="section15_manual",J14,0)))
A15: да | B15: 1 | C15: Подготовительные земельные работы | D15: Бассейн | E15: work | F15: 14 | G15: Выемка и перемещение существующего грунта для устройства бассейна | H15: м.куб. | I15: 210 | J15: 100 | K15: =IF(OR(E15="work",E15="section14_item"),I15*J15,0) | L15: =IF(E15="material",I15*J15,IF(E15="section15_percent",I15/100*(SUMPRODUCT((E$2:E$5000="work")*(B$2:B$5000<>"14")*K$2:K$5000)+SUMPRODUCT((E$2:E$5000="material")*(B$2:B$5000<>"14")*L$2:L$5000)),IF(E15="section15_manual",J15,0)))
A16: да | B16: 1 | C16: Подготовительные земельные работы | D16: Бассейн | E16: work | F16: 15 | G16: Планировка грунта по склону | H16: м.куб. | I16: 210 | J16: 100 | K16: =IF(OR(E16="work",E16="section14_item"),I16*J16,0) | L16: =IF(E16="material",I16*J16,IF(E16="section15_percent",I16/100*(SUMPRODUCT((E$2:E$5000="work")*(B$2:B$5000<>"14")*K$2:K$5000)+SUMPRODUCT((E$2:E$5000="material")*(B$2:B$5000<>"14")*L$2:L$5000)),IF(E16="section15_manual",J16,0)))
A17: да | B17: 1 | C17: Подготовительные земельные работы | D17: Бассейн | E17: work | F17: 16 | G17: Обратная засыпка песком после устройства ж/б конструкций | H17: м.куб. | I17: 12 | J17: 100 | K17: =IF(OR(E17="work",E17="section14_item"),I17*J17,0) | L17: =IF(E17="material",I17*J17,IF(E17="section15_percent",I17/100*(SUMPRODUCT((E$2:E$5000="work")*(B$2:B$5000<>"14")*K$2:K$5000)+SUMPRODUCT((E$2:E$5000="material")*(B$2:B$5000<>"14")*L$2:L$5000)),IF(E17="section15_manual",J17,0)))
A18: да | B18: 1 | C18: Подготовительные земельные работы | D18: Бассейн | E18: material | F18: 17 | G18: Песок намывной (самосвал 20м3) | H18: м.куб. | I18: 13.953488 | J18: 100 | K18: =IF(OR(E18="work",E18="section14_item"),I18*J18,0) | L18: =IF(E18="material",I18*J18,IF(E18="section15_percent",I18/100*(SUMPRODUCT((E$2:E$5000="work")*(B$2:B$5000<>"14")*K$2:K$5000)+SUMPRODUCT((E$2:E$5000="material")*(B$2:B$5000<>"14")*L$2:L$5000)),IF(E18="section15_manual",J18,0))) | M18: 10м3 - 1650р/м3
A19: да | B19: 1 | C19: Подготовительные земельные работы | D19: Бассейн | E19: material | F19: 18 | G19: Грунт от выемки под автомобильное мощение | H19: м.куб. | I19: 16.224986 | J19: 100 | K19: =IF(OR(E19="work",E19="section14_item"),I19*J19,0) | L19: =IF(E19="material",I19*J19,IF(E19="section15_percent",I19/100*(SUMPRODUCT((E$2:E$5000="work")*(B$2:B$5000<>"14")*K$2:K$5000)+SUMPRODUCT((E$2:E$5000="material")*(B$2:B$5000<>"14")*L$2:L$5000)),IF(E19="section15_manual",J19,0)))
A20: да | B20: 1 | C20: Подготовительные земельные работы | D20: Бассейн | E20: work | F20: 19 | G20: Перемещение сыпучих материалов на расстояние до 50м вручную (склон) с коэффициентом сложности | H20: м.куб. | I20: 25 | J20: 100 | K20: =IF(OR(E20="work",E20="section14_item"),I20*J20,0) | L20: =IF(E20="material",I20*J20,IF(E20="section15_percent",I20/100*(SUMPRODUCT((E$2:E$5000="work")*(B$2:B$5000<>"14")*K$2:K$5000)+SUMPRODUCT((E$2:E$5000="material")*(B$2:B$5000<>"14")*L$2:L$5000)),IF(E20="section15_manual",J20,0)))
A21: да | B21: 2 | C21: Дренажная и ливневая системы. | E21: work | F21: 20 | G21: Монтаж водоприемных колодцев 630мм с выемкой | H21: шт. | I21: 1 | J21: 100 | K21: =IF(OR(E21="work",E21="section14_item"),I21*J21,0) | L21: =IF(E21="material",I21*J21,IF(E21="section15_percent",I21/100*(SUMPRODUCT((E$2:E$5000="work")*(B$2:B$5000<>"14")*K$2:K$5000)+SUMPRODUCT((E$2:E$5000="material")*(B$2:B$5000<>"14")*L$2:L$5000)),IF(E21="section15_manual",J21,0)))
A22: да | B22: 2 | C22: Дренажная и ливневая системы. | E22: material | F22: 21 | G22: Колодец фильтрационный конический 600мм h=2м с крышкой | H22: шт. | I22: 1 | J22: 100 | K22: =IF(OR(E22="work",E22="section14_item"),I22*J22,0) | L22: =IF(E22="material",I22*J22,IF(E22="section15_percent",I22/100*(SUMPRODUCT((E$2:E$5000="work")*(B$2:B$5000<>"14")*K$2:K$5000)+SUMPRODUCT((E$2:E$5000="material")*(B$2:B$5000<>"14")*L$2:L$5000)),IF(E22="section15_manual",J22,0)))
A23: да | B23: 2 | C23: Дренажная и ливневая системы. | E23: material | F23: 22 | G23: Щебень гранитный фр.20-40мм (самосвал 20м3) | H23: м.куб. | I23: 0.5 | J23: 100 | K23: =IF(OR(E23="work",E23="section14_item"),I23*J23,0) | L23: =IF(E23="material",I23*J23,IF(E23="section15_percent",I23/100*(SUMPRODUCT((E$2:E$5000="work")*(B$2:B$5000<>"14")*K$2:K$5000)+SUMPRODUCT((E$2:E$5000="material")*(B$2:B$5000<>"14")*L$2:L$5000)),IF(E23="section15_manual",J23,0)))
A24: да | B24: 2 | C24: Дренажная и ливневая системы. | E24: material | F24: 23 | G24: Геотекстиль плотность 200г/м2 | H24: м.кв. | I24: 25 | J24: 100 | K24: =IF(OR(E24="work",E24="section14_item"),I24*J24,0) | L24: =IF(E24="material",I24*J24,IF(E24="section15_percent",I24/100*(SUMPRODUCT((E$2:E$5000="work")*(B$2:B$5000<>"14")*K$2:K$5000)+SUMPRODUCT((E$2:E$5000="material")*(B$2:B$5000<>"14")*L$2:L$5000)),IF(E24="section15_manual",J24,0)))
A25: да | B25: 2 | C25: Дренажная и ливневая системы. | E25: work | F25: 24 | G25: Устройство врезок в существующий колодец | H25: шт. | I25: 3 | J25: 100 | K25: =IF(OR(E25="work",E25="section14_item"),I25*J25,0) | L25: =IF(E25="material",I25*J25,IF(E25="section15_percent",I25/100*(SUMPRODUCT((E$2:E$5000="work")*(B$2:B$5000<>"14")*K$2:K$5000)+SUMPRODUCT((E$2:E$5000="material")*(B$2:B$5000<>"14")*L$2:L$5000)),IF(E25="section15_manual",J25,0)))
A26: да | B26: 2 | C26: Дренажная и ливневая системы. | E26: work | F26: 25 | G26: Монтаж колодцев инспекционных 315мм | H26: шт. | I26: 1 | J26: 100 | K26: =IF(OR(E26="work",E26="section14_item"),I26*J26,0) | L26: =IF(E26="material",I26*J26,IF(E26="section15_percent",I26/100*(SUMPRODUCT((E$2:E$5000="work")*(B$2:B$5000<>"14")*K$2:K$5000)+SUMPRODUCT((E$2:E$5000="material")*(B$2:B$5000<>"14")*L$2:L$5000)),IF(E26="section15_manual",J26,0)))
A27: да | B27: 2 | C27: Дренажная и ливневая системы. | E27: material | F27: 26 | G27: Колодец инспекционный 315мм h=2м с крышкой и дном | H27: шт. | I27: 1 | J27: 100 | K27: =IF(OR(E27="work",E27="section14_item"),I27*J27,0) | L27: =IF(E27="material",I27*J27,IF(E27="section15_percent",I27/100*(SUMPRODUCT((E$2:E$5000="work")*(B$2:B$5000<>"14")*K$2:K$5000)+SUMPRODUCT((E$2:E$5000="material")*(B$2:B$5000<>"14")*L$2:L$5000)),IF(E27="section15_manual",J27,0)))
A28: да | B28: 2 | C28: Дренажная и ливневая системы. | E28: work | F28: 27 | G28: Устройство дренажной системы с обратной засыпкой (глубина до 700мм) | H28: м.п. | I28: 42.3 | J28: 100 | K28: =IF(OR(E28="work",E28="section14_item"),I28*J28,0) | L28: =IF(E28="material",I28*J28,IF(E28="section15_percent",I28/100*(SUMPRODUCT((E$2:E$5000="work")*(B$2:B$5000<>"14")*K$2:K$5000)+SUMPRODUCT((E$2:E$5000="material")*(B$2:B$5000<>"14")*L$2:L$5000)),IF(E28="section15_manual",J28,0)))
A29: да | B29: 2 | C29: Дренажная и ливневая системы. | E29: material | F29: 28 | G29: Геотекстиль плотность 200г/м2 | H29: м.кв. | I29: 25 | J29: 100 | K29: =IF(OR(E29="work",E29="section14_item"),I29*J29,0) | L29: =IF(E29="material",I29*J29,IF(E29="section15_percent",I29/100*(SUMPRODUCT((E$2:E$5000="work")*(B$2:B$5000<>"14")*K$2:K$5000)+SUMPRODUCT((E$2:E$5000="material")*(B$2:B$5000<>"14")*L$2:L$5000)),IF(E29="section15_manual",J29,0)))
A30: да | B30: 2 | C30: Дренажная и ливневая системы. | E30: material | F30: 29 | G30: Труба дренажная 110мм перфорир. в фильтре (бухта 50м) | H30: бухта | I30: 4 | J30: 100 | K30: =IF(OR(E30="work",E30="section14_item"),I30*J30,0) | L30: =IF(E30="material",I30*J30,IF(E30="section15_percent",I30/100*(SUMPRODUCT((E$2:E$5000="work")*(B$2:B$5000<>"14")*K$2:K$5000)+SUMPRODUCT((E$2:E$5000="material")*(B$2:B$5000<>"14")*L$2:L$5000)),IF(E30="section15_manual",J30,0)))
A31: да | B31: 2 | C31: Дренажная и ливневая системы. | E31: material | F31: 30 | G31: Щебень гранитный фр.20-40мм (самосвал 20м3) | H31: м.куб. | I31: 7 | J31: 100 | K31: =IF(OR(E31="work",E31="section14_item"),I31*J31,0) | L31: =IF(E31="material",I31*J31,IF(E31="section15_percent",I31/100*(SUMPRODUCT((E$2:E$5000="work")*(B$2:B$5000<>"14")*K$2:K$5000)+SUMPRODUCT((E$2:E$5000="material")*(B$2:B$5000<>"14")*L$2:L$5000)),IF(E31="section15_manual",J31,0)))
A32: да | B32: 2 | C32: Дренажная и ливневая системы. | E32: material | F32: 31 | G32: Песок намывной (самосвал 20м3) | H32: м.куб. | I32: 7 | J32: 100 | K32: =IF(OR(E32="work",E32="section14_item"),I32*J32,0) | L32: =IF(E32="material",I32*J32,IF(E32="section15_percent",I32/100*(SUMPRODUCT((E$2:E$5000="work")*(B$2:B$5000<>"14")*K$2:K$5000)+SUMPRODUCT((E$2:E$5000="material")*(B$2:B$5000<>"14")*L$2:L$5000)),IF(E32="section15_manual",J32,0)))
... A46: да | B46: 2 | C46: Дренажная и ливневая системы. | E46: material | F46: 45 | G46: Цемент М400, 50кг | H46: меш. | I46: 1 | J46: 100 | K46: =IF(OR(E46="work",E46="section14_item"),I46*J46,0) | L46: =IF(E46="material",I46*J46,IF(E46="section15_percent",I46/100*(SUMPRODUCT((E$2:E$5000="work")*(B$2:B$5000<>"14")*K$2:K$5000)+SUMPRODUCT((E$2:E$5000="material")*(B$2:B$5000<>"14")*L$2:L$5000)),IF(E46="section15_manual",J46,0)))
A47: да | B47: 3 | C47: Монолитные железобетонные конструкции | E47: subsection | F47: 46 | G47: Плита основания - 75м2 | K47: =IF(OR(E47="work",E47="section14_item"),I47*J47,0) | L47: =IF(E47="material",I47*J47,IF(E47="section15_percent",I47/100*(SUMPRODUCT((E$2:E$5000="work")*(B$2:B$5000<>"14")*K$2:K$5000)+SUMPRODUCT((E$2:E$5000="material")*(B$2:B$5000<>"14")*L$2:L$5000)),IF(E47="section15_manual",J47,0)))
A48: да | B48: 3 | C48: Монолитные железобетонные конструкции | D48: Плита основания - 75м2 | E48: work | F48: 47 | G48: Устройство выравнивающих оснований из песка с трамбованием вручную | H48: м.куб. | I48: 9 | J48: 100 | K48: =IF(OR(E48="work",E48="section14_item"),I48*J48,0) | L48: =IF(E48="material",I48*J48,IF(E48="section15_percent",I48/100*(SUMPRODUCT((E$2:E$5000="work")*(B$2:B$5000<>"14")*K$2:K$5000)+SUMPRODUCT((E$2:E$5000="material")*(B$2:B$5000<>"14")*L$2:L$5000)),IF(E48="section15_manual",J48,0)))
A49: да | B49: 3 | C49: Монолитные железобетонные конструкции | D49: Плита основания - 75м2 | E49: material | F49: 48 | G49: Песок намывной (самосвал 20м3) | H49: м.куб. | I49: 11.7 | J49: 100 | K49: =IF(OR(E49="work",E49="section14_item"),I49*J49,0) | L49: =IF(E49="material",I49*J49,IF(E49="section15_percent",I49/100*(SUMPRODUCT((E$2:E$5000="work")*(B$2:B$5000<>"14")*K$2:K$5000)+SUMPRODUCT((E$2:E$5000="material")*(B$2:B$5000<>"14")*L$2:L$5000)),IF(E49="section15_manual",J49,0)))
A50: да | B50: 3 | C50: Монолитные железобетонные конструкции | D50: Плита основания - 75м2 | E50: work | F50: 49 | G50: Аренда виброплиты 250кг | H50: смена | I50: 1 | J50: 100 | K50: =IF(OR(E50="work",E50="section14_item"),I50*J50,0) | L50: =IF(E50="material",I50*J50,IF(E50="section15_percent",I50/100*(SUMPRODUCT((E$2:E$5000="work")*(B$2:B$5000<>"14")*K$2:K$5000)+SUMPRODUCT((E$2:E$5000="material")*(B$2:B$5000<>"14")*L$2:L$5000)),IF(E50="section15_manual",J50,0)))
A51: да | B51: 3 | C51: Монолитные железобетонные конструкции | D51: Плита основания - 75м2 | E51: work | F51: 50 | G51: Укладка геотекстиля | H51: м.кв. | I51: 90 | J51: 100 | K51: =IF(OR(E51="work",E51="section14_item"),I51*J51,0) | L51: =IF(E51="material",I51*J51,IF(E51="section15_percent",I51/100*(SUMPRODUCT((E$2:E$5000="work")*(B$2:B$5000<>"14")*K$2:K$5000)+SUMPRODUCT((E$2:E$5000="material")*(B$2:B$5000<>"14")*L$2:L$5000)),IF(E51="section15_manual",J51,0)))
A52: да | B52: 3 | C52: Монолитные железобетонные конструкции | D52: Плита основания - 75м2 | E52: material | F52: 51 | G52: Геотекстиль плотность 200г/м2 | H52: м.кв. | I52: 108 | J52: 100 | K52: =IF(OR(E52="work",E52="section14_item"),I52*J52,0) | L52: =IF(E52="material",I52*J52,IF(E52="section15_percent",I52/100*(SUMPRODUCT((E$2:E$5000="work")*(B$2:B$5000<>"14")*K$2:K$5000)+SUMPRODUCT((E$2:E$5000="material")*(B$2:B$5000<>"14")*L$2:L$5000)),IF(E52="section15_manual",J52,0)))
A53: да | B53: 3 | C53: Монолитные железобетонные конструкции | D53: Плита основания - 75м2 | E53: work | F53: 52 | G53: Устройство оснований из щебня с трамбованием, расклинцовкой вручную | H53: м.куб. | I53: 13.5 | J53: 100 | K53: =IF(OR(E53="work",E53="section14_item"),I53*J53,0) | L53: =IF(E53="material",I53*J53,IF(E53="section15_percent",I53/100*(SUMPRODUCT((E$2:E$5000="work")*(B$2:B$5000<>"14")*K$2:K$5000)+SUMPRODUCT((E$2:E$5000="material")*(B$2:B$5000<>"14")*L$2:L$5000)),IF(E53="section15_manual",J53,0)))
...

Sheet Печатная форма
C1: Ландшафтная студия БОТАНИК Бухарестская ул., д. 110, к. 1 Санкт-Петербург, 192288
B8: Коммерческое предложение №__________.
B9: Расчет цен произведен __.___.202__г. (цены действительны в течение 7 календарных дней с даты расчета).
B11: Заказчик: ____________________________________________________________
B12: Исполнитель: Ландшафтная студия БОТАНИК
B13: Адрес проведения работ:
B15: Сроки проведения работ:
B16: начало
B17: окончание
B19: Работы по благоустройству.
B20: Наименование работ | G20: Стоимость
A21: 1 | B21: Подготовительные земельные работы | G21: =SUMIFS(Расчет!K:K,Расчет!B:B,"1",Расчет!E:E,"work")+SUMIFS(Расчет!K:K,Расчет!B:B,"1",Расчет!E:E,"section14_item")+SUMIFS(Расчет!L:L,Расчет!B:B,"1")
A22: 2 | B22: Дренажная и ливневая системы. | G22: =SUMIFS(Расчет!K:K,Расчет!B:B,"2",Расчет!E:E,"work")+SUMIFS(Расчет!K:K,Расчет!B:B,"2",Расчет!E:E,"section14_item")+SUMIFS(Расчет!L:L,Расчет!B:B,"2")
A23: 3 | B23: Монолитные железобетонные конструкции | G23: =SUMIFS(Расчет!K:K,Расчет!B:B,"3",Расчет!E:E,"work")+SUMIFS(Расчет!K:K,Расчет!B:B,"3",Расчет!E:E,"section14_item")+SUMIFS(Расчет!L:L,Расчет!B:B,"3")
A24: 4 | B24: Подпорные стенки, ступени - верхняя зона | G24: =SUMIFS(Расчет!K:K,Расчет!B:B,"4",Расчет!E:E,"work")+SUMIFS(Расчет!K:K,Расчет!B:B,"4",Расчет!E:E,"section14_item")+SUMIFS(Расчет!L:L,Расчет!B:B,"4")
A25: 5 | B25: Покрытия. | G25: =SUMIFS(Расчет!K:K,Расчет!B:B,"5",Расчет!E:E,"work")+SUMIFS(Расчет!K:K,Расчет!B:B,"5",Расчет!E:E,"section14_item")+SUMIFS(Расчет!L:L,Расчет!B:B,"5")
A26: 6 | B26: Лестница в нижнюю часть участка | G26: =SUMIFS(Расчет!K:K,Расчет!B:B,"6",Расчет!E:E,"work")+SUMIFS(Расчет!K:K,Расчет!B:B,"6",Расчет!E:E,"section14_item")+SUMIFS(Расчет!L:L,Расчет!B:B,"6")
A27: 7 | B27: Террасные настилы. | G27: =SUMIFS(Расчет!K:K,Расчет!B:B,"7",Расчет!E:E,"work")+SUMIFS(Расчет!K:K,Расчет!B:B,"7",Расчет!E:E,"section14_item")+SUMIFS(Расчет!L:L,Расчет!B:B,"7")
A28: 8 | B28: Освещение. | G28: =SUMIFS(Расчет!K:K,Расчет!B:B,"8",Расчет!E:E,"work")+SUMIFS(Расчет!K:K,Расчет!B:B,"8",Расчет!E:E,"section14_item")+SUMIFS(Расчет!L:L,Расчет!B:B,"8")
A29: 9 | B29: Газон. | G29: =SUMIFS(Расчет!K:K,Расчет!B:B,"9",Расчет!E:E,"work")+SUMIFS(Расчет!K:K,Расчет!B:B,"9",Расчет!E:E,"section14_item")+SUMIFS(Расчет!L:L,Расчет!B:B,"9")
A30: 10 | B30: Ограждение стеклянное | G30: =SUMIFS(Расчет!K:K,Расчет!B:B,"10",Расчет!E:E,"work")+SUMIFS(Расчет!K:K,Расчет!B:B,"10",Расчет!E:E,"section14_item")+SUMIFS(Расчет!L:L,Расчет!B:B,"10")
A31: 11 | B31: Автополив | G31: =SUMIFS(Расчет!K:K,Расчет!B:B,"11",Расчет!E:E,"work")+SUMIFS(Расчет!K:K,Расчет!B:B,"11",Расчет!E:E,"section14_item")+SUMIFS(Расчет!L:L,Расчет!B:B,"11")
A32: 12 | B32: Бассейн | G32: =SUMIFS(Расчет!K:K,Расчет!B:B,"12",Расчет!E:E,"work")+SUMIFS(Расчет!K:K,Расчет!B:B,"12",Расчет!E:E,"section14_item")+SUMIFS(Расчет!L:L,Расчет!B:B,"12")
A33: 13 | B33: Антиобледенение | G33: =SUMIFS(Расчет!K:K,Расчет!B:B,"13",Расчет!E:E,"work")+SUMIFS(Расчет!K:K,Расчет!B:B,"13",Расчет!E:E,"section14_item")+SUMIFS(Расчет!L:L,Расчет!B:B,"13")
A34: 14 | B34: Вывоз грунта (по факту) | G34: =SUMIFS(Расчет!K:K,Расчет!B:B,"14",Расчет!E:E,"work")+SUMIFS(Расчет!K:K,Расчет!B:B,"14",Расчет!E:E,"section14_item")+SUMIFS(Расчет!L:L,Расчет!B:B,"14")
A35: 15 | B35: Организационные затраты (предварительно) | G35: =SUMIFS(Расчет!K:K,Расчет!B:B,"15",Расчет!E:E,"work")+SUMIFS(Расчет!K:K,Расчет!B:B,"15",Расчет!E:E,"section14_item")+SUMIFS(Расчет!L:L,Расчет!B:B,"15")
B36: ВСЕГО по смете: | G36: =SUM(G21:G35)
A39: 1. | B39: Подготовительные земельные работы | C39: Ед. изм. | D39: Кол-во | E39: Цена | F39: Работы | G39: Материалы | H39: Примечание
A40: 1 | B40: =Расчет!G2 | C40: =Расчет!H2 | D40: =Расчет!I2 | E40: =Расчет!J2 | F40: =Расчет!K2 | H40: =Расчет!M2
A41: 2 | B41: =Расчет!G3 | C41: =Расчет!H3 | D41: =Расчет!I3 | E41: =Расчет!J3 | F41: =Расчет!K3 | H41: =Расчет!M3
A42: 3 | B42: =Расчет!G4 | C42: =Расчет!H4 | D42: =Расчет!I4 | E42: =Расчет!J4 | F42: =Расчет!K4 | H42: =Расчет!M4
A43: 4 | B43: =Расчет!G5 | C43: =Расчет!H5 | D43: =Расчет!I5 | E43: =Расчет!J5 | F43: =Расчет!K5 | H43: =Расчет!M5
B44: =Расчет!G6 | C44: =Расчет!H6 | D44: =Расчет!I6 | E44: =Расчет!J6 | G44: =Расчет!L6 | H44: =Расчет!M6
A45: 5 | B45: =Расчет!G7 | C45: =Расчет!H7 | D45: =Расчет!I7 | E45: =Расчет!J7 | F45: =Расчет!K7 | H45: =Расчет!M7
A46: 6 | B46: =Расчет!G8 | C46: =Расчет!H8 | D46: =Расчет!I8 | E46: =Расчет!J8 | F46: =Расчет!K8 | H46: =Расчет!M8
B47: Нижняя зона участка
A48: 7 | B48: =Расчет!G10 | C48: =Расчет!H10 | D48: =Расчет!I10 | E48: =Расчет!J10 | F48: =Расчет!K10 | H48: =Расчет!M10
A49: 8 | B49: =Расчет!G11 | C49: =Расчет!H11 | D49: =Расчет!I11 | E49: =Расчет!J11 | F49: =Расчет!K11 | H49: =Расчет!M11
A50: 9 | B50: =Расчет!G12 | C50: =Расчет!H12 | D50: =Расчет!I12 | E50: =Расчет!J12 | F50: =Расчет!K12 | H50: =Расчет!M12
A51: 10 | B51: =Расчет!G13 | C51: =Расчет!H13 | D51: =Расчет!I13 | E51: =Расчет!J13 | F51: =Расчет!K13 | H51: =Расчет!M13
...
